Workbook

Sheet Sheet2
A1: id | B1: tname | C1: school | D1: association | E1: AllGross | F1: limit80C | G1: Gross80D | H1: TaxableIncome | I1: NetTax | J1: AddedEduCess
A2: =IF(Sheet1!B2<>"",Sheet1!B2,"") -> teachers101 | B2: =IF(Sheet1!C2<>"",Sheet1!C2,"") -> SOHINI PAUL | C2: =IF(Sheet1!D2<>"",Sheet1!D2,"") -> AMORAGORI GIRLS PRIMARY SCHOOL | D2: =IF(Sheet1!E2<>"",Sheet1!E2,"") -> WBTPTA | E2: =IF(Sheet1!DY2<>"",Sheet1!DY2,"") -> 415160 | F2: =IF(Sheet1!EQ2<>"",Sheet1!EQ2,"") -> 24000 | G2: =IF(Sheet1!EZ2<>"",Sheet1!EZ2,"") -> 0 | H2: =IF(Sheet1!FA2<>"",Sheet1!FA2,"") -> 339360 | I2: =IF(Sheet1!FI2<>"",Sheet1!FI2,"") -> 0 | J2: =IF(Sheet1!GI2<>"",Sheet1!GI2,"") -> 0
A3: =IF(Sheet1!B3<>"",Sheet1!B3,"") -> teachers102 | B3: =IF(Sheet1!C3<>"",Sheet1!C3,"") -> MOUMITA MAJI | C3: =IF(Sheet1!D3<>"",Sheet1!D3,"") -> AMORAGORI GIRLS PRIMARY SCHOOL | D3: =IF(Sheet1!E3<>"",Sheet1!E3,"") -> WBTPTA | E3: =IF(Sheet1!DY3<>"",Sheet1!DY3,"") -> 464456 | F3: =IF(Sheet1!EQ3<>"",Sheet1!EQ3,"") -> 24000 | G3: =IF(Sheet1!EZ3<>"",Sheet1!EZ3,"") -> 0 | H3: =IF(Sheet1!FA3<>"",Sheet1!FA3,"") -> 388656 | I3: =IF(Sheet1!FI3<>"",Sheet1!FI3,"") -> 0 | J3: =IF(Sheet1!GI3<>"",Sheet1!GI3,"") -> 0
A4: =IF(Sheet1!B4<>"",Sheet1!B4,"") -> teachers103 | B4: =IF(Sheet1!C4<>"",Sheet1!C4,"") -> RAGHABENDRA KOLEY | C4: =IF(Sheet1!D4<>"",Sheet1!D4,"") -> BANCHARAM ROY PRIMARY SCHOOL | D4: =IF(Sheet1!E4<>"",Sheet1!E4,"") -> WBTPTA | E4: =IF(Sheet1!DY4<>"",Sheet1!DY4,"") -> 712284 | F4: =IF(Sheet1!EQ4<>"",Sheet1!EQ4,"") -> 36000 | G4: =IF(Sheet1!EZ4<>"",Sheet1!EZ4,"") -> 50000 | H4: =IF(Sheet1!FA4<>"",Sheet1!FA4,"") -> 576284 | I4: =IF(Sheet1!FI4<>"",Sheet1!FI4,"") -> 28867 | J4: =IF(Sheet1!GI4<>"",Sheet1!GI4,"") -> 0
A5: =IF(Sheet1!B5<>"",Sheet1!B5,"") -> teachers104 | B5: =IF(Sheet1!C5<>"",Sheet1!C5,"") -> AVISHEK CHOWDHURY | C5: =IF(Sheet1!D5<>"",Sheet1!D5,"") -> BANCHARAM ROY PRIMARY SCHOOL | D5: =IF(Sheet1!E5<>"",Sheet1!E5,"") -> WBTPTA | E5: =IF(Sheet1!DY5<>"",Sheet1!DY5,"") -> 385532 | F5: =IF(Sheet1!EQ5<>"",Sheet1!EQ5,"") -> 8000 | G5: =IF(Sheet1!EZ5<>"",Sheet1!EZ5,"") -> 0 | H5: =IF(Sheet1!FA5<>"",Sheet1!FA5,"") -> 325732 | I5: =IF(Sheet1!FI5<>"",Sheet1!FI5,"") -> 0 | J5: =IF(Sheet1!GI5<>"",Sheet1!GI5,"") -> 0
A6: =IF(Sheet1!B6<>"",Sheet1!B6,"") -> teachers105 | B6: =IF(Sheet1!C6<>"",Sheet1!C6,"") -> AMIT RIT | C6: =IF(Sheet1!D6<>"",Sheet1!D6,"") -> BAR GAZIPUR PRIMARY SCHOOL | D6: =IF(Sheet1!E6<>"",Sheet1!E6,"") -> ABPTA | E6: =IF(Sheet1!DY6<>"",Sheet1!DY6,"") -> 527060 | F6: =IF(Sheet1!EQ6<>"",Sheet1!EQ6,"") -> 48000 | G6: =IF(Sheet1!EZ6<>"",Sheet1!EZ6,"") -> 0 | H6: =IF(Sheet1!FA6<>"",Sheet1!FA6,"") -> 426660 | I6: =IF(Sheet1!FI6<>"",Sheet1!FI6,"") -> 0 | J6: =IF(Sheet1!GI6<>"",Sheet1!GI6,"") -> 0
A7: =IF(Sheet1!B7<>"",Sheet1!B7,"") -> teachers106 | B7: =IF(Sheet1!C7<>"",Sheet1!C7,"") -> TAPAS KARMAKAR | C7: =IF(Sheet1!D7<>"",Sheet1!D7,"") -> BAR GAZIPUR PRIMARY SCHOOL | D7: =IF(Sheet1!E7<>"",Sheet1!E7,"") -> WBTPTA | E7: =IF(Sheet1!DY7<>"",Sheet1!DY7,"") -> 415160 | F7: =IF(Sheet1!EQ7<>"",Sheet1!EQ7,"") -> 24000 | G7: =IF(Sheet1!EZ7<>"",Sheet1!EZ7,"") -> 0 | H7: =IF(Sheet1!FA7<>"",Sheet1!FA7,"") -> 339360 | I7: =IF(Sheet1!FI7<>"",Sheet1!FI7,"") -> 0 | J7: =IF(Sheet1!GI7<>"",Sheet1!GI7,"") -> 0
A8: =IF(Sheet1!B8<>"",Sheet1!B8,"") -> teachers107 | B8: =IF(Sheet1!C8<>"",Sheet1!C8,"") -> BIKASH CHANDRA DALUI | C8: =IF(Sheet1!D8<>"",Sheet1!D8,"") -> BER DHAIPUR PRIMARY SCHOOL | D8: =IF(Sheet1!E8<>"",Sheet1!E8,"") -> WBPTA | E8: =IF(Sheet1!DY8<>"",Sheet1!DY8,"") -> 717084 | F8: =IF(Sheet1!EQ8<>"",Sheet1!EQ8,"") -> 36000 | G8: =IF(Sheet1!EZ8<>"",Sheet1!EZ8,"") -> 0 | H8: =IF(Sheet1!FA8<>"",Sheet1!FA8,"") -> 628684 | I8: =IF(Sheet1!FI8<>"",Sheet1!FI8,"") -> 39766 | J8: =IF(Sheet1!GI8<>"",Sheet1!GI8,"") -> 0
A9: =IF(Sheet1!B9<>"",Sheet1!B9,"") -> teachers108 | B9: =IF(Sheet1!C9<>"",Sheet1!C9,"") -> SUPARNA GHOSH | C9: =IF(Sheet1!D9<>"",Sheet1!D9,"") -> BER DHAIPUR PRIMARY SCHOOL | D9: =IF(Sheet1!E9<>"",Sheet1!E9,"") -> WBTPTA | E9: =IF(Sheet1!DY9<>"",Sheet1!DY9,"") -> 522260 | F9: =IF(Sheet1!EQ9<>"",Sheet1!EQ9,"") -> 60000 | G9: =IF(Sheet1!EZ9<>"",Sheet1!EZ9,"") -> 0 | H9: =IF(Sheet1!FA9<>"",Sheet1!FA9,"") -> 409860 | I9: =IF(Sheet1!FI9<>"",Sheet1!FI9,"") -> 0 | J9: =IF(Sheet1!GI9<>"",Sheet1!GI9,"") -> 0
A10: =IF(Sheet1!B10<>"",Sheet1!B10,"") -> teachers109 | B10: =IF(Sheet1!C10<>"",Sheet1!C10,"") -> SOHEL REJA | C10: =IF(Sheet1!D10<>"",Sheet1!D10,"") -> BER DHAIPUR PRIMARY SCHOOL | D10: =IF(Sheet1!E10<>"",Sheet1!E10,"") -> WBTPTA | E10: =IF(Sheet1!DY10<>"",Sheet1!DY10,"") -> 415160 | F10: =IF(Sheet1!EQ10<>"",Sheet1!EQ10,"") -> 24000 | G10: =IF(Sheet1!EZ10<>"",Sheet1!EZ10,"") -> 0 | H10: =IF(Sheet1!FA10<>"",Sheet1!FA10,"") -> 339360 | I10: =IF(Sheet1!FI10<>"",Sheet1!FI10,"") -> 0 | J10: =IF(Sheet1!GI10<>"",Sheet1!GI10,"") -> 0
A11: =IF(Sheet1!B11<>"",Sheet1!B11,"") -> teachers110 | B11: =IF(Sheet1!C11<>"",Sheet1!C11,"") -> TARUN GHARA | C11: =IF(Sheet1!D11<>"",Sheet1!D11,"") -> BER DHAIPUR PRIMARY SCHOOL | D11: =IF(Sheet1!E11<>"",Sheet1!E11,"") -> WBTPTA | E11: =IF(Sheet1!DY11<>"",Sheet1!DY11,"") -> 406054 | F11: =IF(Sheet1!EQ11<>"",Sheet1!EQ11,"") -> 2000 | G11: =IF(Sheet1!EZ11<>"",Sheet1!EZ11,"") -> 0 | H11: =IF(Sheet1!FA11<>"",Sheet1!FA11,"") -> 352404 | I11: =IF(Sheet1!FI11<>"",Sheet1!FI11,"") -> 0 | J11: =IF(Sheet1!GI11<>"",Sheet1!GI11,"") -> 0
A12: =IF(Sheet1!B12<>"",Sheet1!B12,"") -> teachers111 | B12: =IF(Sheet1!C12<>"",Sheet1!C12,"") -> SWAPAN DAS | C12: =IF(Sheet1!D12<>"",Sheet1!D12,"") -> BETAI PC PRIMARY SCHOOL | D12: =IF(Sheet1!E12<>"",Sheet1!E12,"") -> WBTPTA | E12: =IF(Sheet1!DY12<>"",Sheet1!DY12,"") -> 711084 | F12: =IF(Sheet1!EQ12<>"",Sheet1!EQ12,"") -> 36000 | G12: =IF(Sheet1!EZ12<>"",Sheet1!EZ12,"") -> 0 | H12: =IF(Sheet1!FA12<>"",Sheet1!FA12,"") -> 622684 | I12: =IF(Sheet1!FI12<>"",Sheet1!FI12,"") -> 38518 | J12: =IF(Sheet1!GI12<>"",Sheet1!GI12,"") -> 0
A13: =IF(Sheet1!B13<>"",Sheet1!B13,"") -> teachers112 | B13: =IF(Sheet1!C13<>"",Sheet1!C13,"") -> RAJU KOLEY | C13: =IF(Sheet1!D13<>"",Sheet1!D13,"") -> BETAI PC PRIMARY SCHOOL | D13: =IF(Sheet1!E13<>"",Sheet1!E13,"") -> WBTPTA | E13: =IF(Sheet1!DY13<>"",Sheet1!DY13,"") -> 415160 | F13: =IF(Sheet1!EQ13<>"",Sheet1!EQ13,"") -> 24000 | G13: =IF(Sheet1!EZ13<>"",Sheet1!EZ13,"") -> 0 | H13: =IF(Sheet1!FA13<>"",Sheet1!FA13,"") -> 339360 | I13: =IF(Sheet1!FI13<>"",Sheet1!FI13,"") -> 0 | J13: =IF(Sheet1!GI13<>"",Sheet1!GI13,"") -> 0
... A400: =IF(Sheet1!B400<>"",Sheet1!B400,"") | B400: =IF(Sheet1!C400<>"",Sheet1!C400,"") | C400: =IF(Sheet1!D400<>"",Sheet1!D400,"") | D400: =IF(Sheet1!E400<>"",Sheet1!E400,"") | E400: =IF(Sheet1!DY400<>"",Sheet1!DY400,"") | F400: =IF(Sheet1!EQ400<>"",Sheet1!EQ400,"") | G400: =IF(Sheet1!EZ400<>"",Sheet1!EZ400,"") | H400: =IF(Sheet1!FA400<>"",Sheet1!FA400,"") | I400: =IF(Sheet1!FI400<>"",Sheet1!FI400,"") | J400: =IF(Sheet1!GI400<>"",Sheet1!GI400,"")

Sheet Sheet1
A1: sl | B1: id | C1: tname | D1: school | E1: association | F1: disability | G1: bonus | H1: marchBasic | I1: marchDA | J1: marchHRA | K1: marchAddl | L1: marchMA | M1: marchGross | N1: marchGPF | O1: marchGSLI | P1: marchPTAX | Q1: marchNetpay | R1: aprilBasic | S1: aprilDA | T1: aprilHRA | U1: aprilAddl | V1: aprilMA | W1: aprilGross | X1: aprilGPF | Y1: aprilGSLI | Z1: aprilPTAX | AA1: aprilNetpay | AB1: mayBasic | AC1: mayDA | AD1: mayHRA | AE1: mayAddl | AF1: mayMA | AG1: mayGross | AH1: mayGPF | AI1: mayGSLI | AJ1: mayPTAX | AK1: mayNetpay | AL1: juneBasic | AM1: juneDA | AN1: juneHRA | AO1: juneAddl | AP1: juneMA | AQ1: juneGross | AR1: juneGPF | AS1: juneGSLI | AT1: junePTAX | AU1: juneNetpay | AV1: julyBasic | AW1: julyDA | AX1: aprilIR | AY1: julyHRA | AZ1: julyAddl | BA1: julyMA | BB1: julyGross | BC1: julyGPF | BD1: julyGSLI | BE1: julyPTAX | BF1: julyNetpay | BG1: augustBasic | BH1: augustDA | BI1: augustHRA | BJ1: augustAddl | BK1: augustMA | BL1: augustGross | BM1: augustGPF | BN1: augustGSLI | BO1: augustPTAX | BP1: augustNetpay | BQ1: septemberBasic | BR1: septemberDA | BS1: septemberHRA | BT1: septemberAddl | BU1: septemberMA | BV1: septemberGross | BW1: septemberGPF | BX1: septemberGSLI | BY1: septemberPTAX | BZ1: septemberNetpay | CA1: octoberBasic | CB1: octoberDA | CC1: octoberHRA | CD1: octoberAddl | CE1: octoberMA | CF1: octoberGross | CG1: octoberGPF | CH1: octoberGSLI | CI1: octoberPTAX | CJ1: octoberNetpay | CK1: novemberBasic | CL1: novemberDA | CM1: novemberHRA | CN1: novemberAddl | CO1: novemberMA | CP1: novemberGross | CQ1: novemberGPF | CR1: novemberGSLI | CS1: novemberPTAX | CT1: novemberNetpay | CU1: decemberBasic | CV1: decemberDA | CW1: decemberHRA | CX1: decemberAddl | CY1: decemberMA | CZ1: decemberGross | DA1: decemberGPF | DB1: decemberGSLI | DC1: decemberPTAX | DD1: decemberNetpay | DE1: januaryBasic | DF1: januaryDA | DG1: januaryHRA | DH1: januaryAddl | DI1: januaryMA | DJ1: januaryGross | DK1: januaryGPF | DL1: januaryGSLI | DM1: januaryPTAX | DN1: januaryNetpay | DO1: februaryBasic | DP1: februaryDA | DQ1: februaryHRA | DR1: februaryAddl | DS1: februaryMA | DT1: februaryGross | DU1: februaryGPF | DV1: februaryGSLI | DW1: februaryPTAX | DX1: februaryNetpay | DY1: AllGross | DZ1: GrossPTAX | EA1: StandardDeduction | EB1: hbLoanInterest | EC1: GrossIncome | ED1: GrossGPF | EE1: GrossGSLI | EF1: hbLoanPrincipal | EG1: lic | EH1: fd | EI1: ulip | EJ1: ppf | EK1: nsc | EL1: nscInterest | EM1: tutionFee | EN1: sukanya | EO1: stampDuty | EP1: Gross80C | EQ1: limit80C | ER1: After80CDeduction | ES1: mediclaim | ET1: terminalDisease | EU1: handicapTreatment | EV1: educationLoan | EW1: charity | EX1: rgSaving | EY1: otherIncome | EZ1: Gross80D | FA1: TaxableIncome | FB1: firstSlabDeduction | FC1: IncomeTaxStepOne | FD1: IncomeTaxStepTwo | FE1: Rebate | FF1: EduCess | FG1: addEduCess | FH1: tds | FI1: NetTax | FJ1: above5Lakh | FK1: BankInterest | FL1: GrossTotalIncome | FM1: standardDeductionNew | FN1: GrossIncomeNew | FO1: ThirtyIT | FP1: ThirtyITTax | FQ1: TwentyIT | FR1: TwentyITTax | FS1: FifteenIT | FT1: FifteenITTax | FU1: TenIT | FV1: TenITTax | FW1: FiveIT | FX1: FiveITTax | FY1: CalculatedIT | FZ1: cal1 | GA1: cal2 | GB1: cal3 | GC1: cal4 | GD1: cal5 | GE1: cal6 | GF1: GrossRelief | GG1: IncomeTaxAfterRelief | GH1: eduCess | GI1: AddedEduCess
A2: =_xlfn.AGGREGATE(3,5,$B$2:B2) -> 1 | B2: teachers101 | C2: SOHINI PAUL | D2: AMORAGORI GIRLS PRIMARY SCHOOL | E2: WBTPTA | F2: 0 | G2: 6000 | H2: 26200 | I2: =H2*0.1 -> 2620 | J2: =H2*0.12 -> 3144 | K2: 0 | L2: 500 | M2: =SUM(H2:L2) -> 32464 | N2: 2000 | O2: 0 | P2: =IF($F2=50000,0,IF(M2>40000,200,IF(M2>25000,150,IF(M2>15000,130,IF(M2>10000,110,0))))) -> 150 | Q2: =M2-N2-O2-P2 -> 30314 | R2: 26200 | S2: =R2*0.1 -> 2620 | T2: =R2*0.12 -> 3144 | U2: 0 | V2: 500 | W2: =SUM(R2:V2) -> 32464 | X2: 2000 | Y2: 0 | Z2: =IF($F2=50000,0,IF(W2>40000,200,IF(W2>25000,150,IF(W2>15000,130,IF(W2>10000,110,0))))) -> 150 | AA2: =W2-X2-Y2-Z2 -> 30314 | AB2: 26200 | AC2: =AB2*0.14 -> 3668 | AD2: =AB2*0.12 -> 3144 | AE2: 0 | AF2: 500 | AG2: =SUM(AB2:AF2) -> 33512 | AH2: 2000 | AI2: 0 | AJ2: =IF($F2=50000,0,IF(AG2>40000,200,IF(AG2>25000,150,IF(AG2>15000,130,IF(AG2>10000,110,0))))) -> 150 | AK2: =AG2-AH2-AI2-AJ2 -> 31362 | AL2: 26200 | AM2: =AL2*0.14 -> 3668 | AN2: =AL2*0.12 -> 3144 | AO2: 0 | AP2: 500 | AQ2: =SUM(AL2:AP2) -> 33512 | AR2: 2000 | AS2: 0 | AT2: =IF($F2=50000,0,IF(AQ2>40000,200,IF(AQ2>25000,150,IF(AQ2>15000,130,IF(AQ2>10000,110,0))))) -> 150 | AU2: =AQ2-AR2-AS2-AT2 -> 31362 | AV2: 27000 | AW2: =AV2*0.14 -> 3780 | AX2: =R2*0.04 -> 1048 | AY2: =AV2*0.12 -> 3240 | AZ2: 0 | BA2: 500 | BB2: =SUM(AV2:BA2) -> 35568 | BC2: 2000 | BD2: 0 | BE2: =IF($F2=50000,0,IF(BB2>40000,200,IF(BB2>25000,150,IF(BB2>15000,130,IF(BB2>10000,110,0))))) -> 150 | BF2: =BB2-BC2-BD2-BE2 -> 33418 | BG2: 27000 | BH2: =BG2*0.14 -> 3780 | BI2: =BG2*0.12 -> 3240 | BJ2: 0 | BK2: 500 | BL2: =SUM(BG2:BK2) -> 34520 | BM2: 2000 | BN2: 0 | BO2: =IF($F2=50000,0,IF(BL2>40000,200,IF(BL2>25000,150,IF(BL2>15000,130,IF(BL2>10000,110,0))))) -> 150 | BP2: =BL2-BM2-BN2-BO2 -> 32370 | BQ2: 27000 | BR2: =BQ2*0.14 -> 3780 | BS2: =BQ2*0.12 -> 3240 | BT2: 0 | BU2: 500 | BV2: =SUM(BQ2:BU2) -> 34520 | BW2: 2000 | BX2: 0 | BY2: =IF($F2=50000,0,IF(BV2>40000,200,IF(BV2>25000,150,IF(BV2>15000,130,IF(BV2>10000,110,0))))) -> 150 | BZ2: =BV2-BW2-BX2-BY2 -> 32370 | CA2: 27000 | CB2: =CA2*0.14 -> 3780 | CC2: =CA2*0.12 -> 3240 | CD2: 0 | CE2: 500 | CF2: =SUM(CA2:CE2) -> 34520 | CG2: 2000 | CH2: 0 | CI2: =IF($F2=50000,0,IF(CF2>40000,200,IF(CF2>25000,150,IF(CF2>15000,130,IF(CF2>10000,110,0))))) -> 150 | CJ2: =CF2-CG2-CH2-CI2 -> 32370 | CK2: 27000 | CL2: =CK2*0.14 -> 3780 | CM2: =CK2*0.12 -> 3240 | CN2: 0 | CO2: 500 | CP2: =SUM(CK2:CO2) -> 34520 | CQ2: 2000 | CR2: 0 | CS2: =IF($F2=50000,0,IF(CP2>40000,200,IF(CP2>25000,150,IF(CP2>15000,130,IF(CP2>10000,110,0))))) -> 150 | CT2: =CP2-CQ2-CR2-CS2 -> 32370 | CU2: 27000 | CV2: =ROUND(CU2*0.14,0) -> 3780 | CW2: =ROUND(CU2*0.12,0) -> 3240 | CX2: 0 | CY2: 500 | CZ2: =SUM(CU2:CY2) -> 34520 | DA2: 2000 | DB2: 0 | DC2: =IF($F2=50000,0,IF(CZ2>40000,200,IF(CZ2>25000,150,IF(CZ2>15000,130,IF(CZ2>10000,110,0))))) -> 150 | DD2: =CZ2-DA2-DB2-DC2 -> 32370 | DE2: 27000 | DF2: =DE2*0.14 -> 3780 | DG2: =DE2*0.12 -> 3240 | DH2: 0 | DI2: 500 | DJ2: =SUM(DE2:DI2) -> 34520 | DK2: 2000 | DL2: 0 | DM2: =IF($F2=50000,0,IF(DJ2>40000,200,IF(DJ2>25000,150,IF(DJ2>15000,130,IF(DJ2>10000,110,0))))) -> 150 | DN2: =DJ2-DK2-DL2-DM2 -> 32370 | DO2: 27000 | DP2: =DO2*0.14 -> 3780 | DQ2: =DO2*0.12 -> 3240 | DR2: 0 | DS2: 500 | DT2: =SUM(DO2:DS2) -> 34520 | DU2: 2000 | DV2: 0 | DW2: =IF($F2=50000,0,IF(DT2>40000,200,IF(DT2>25000,150,IF(DT2>15000,130,IF(DT2>10000,110,0))))) -> 150 | DX2: =DT2-DU2-DV2-DW2 -> 32370 | DY2: =DT2+DJ2+CZ2+CP2+CF2+BV2+BL2+BB2+AQ2+AG2+W2+M2+G2 -> 415160 | DZ2: =DW2+DM2+DC2+CS2+CI2+BY2+BO2+BE2+AT2+AJ2+Z2+P2 -> 1800 | EA2: =IF(DY2>0,50000,0) -> 50000 | EB2: 0 | EC2: =DY2-DZ2-EA2 -> 363360 | ED2: =DU2+DK2+DA2+CQ2+CG2+BW2+BM2+BC2+AR2+AH2+X2+N2 -> 24000 | EE2: =DV2+DL2+DB2+CR2+CH2+BX2+BN2+BD2+AS2+AI2+Y2+O2 -> 0 | EF2: 0 | EG2: 0 | EH2: 0 | EI2: 0 | EJ2: 0 | EK2: 0 | EL2: 0 | EM2: 0 | EN2: 0 | EO2: 0 | EP2: =SUM(ED2:EO2) -> 24000 | EQ2: =IF(EP2>=150000,150000,EP2) -> 24000 | ER2: =EC2-EQ2 -> 339360 | ES2: 0 | ET2: 0 | EU2: 0 | EV2: 0 | EW2: 0 | EX2: 0 | EY2: 0 | EZ2: =SUM(ES2:EY2)+F2 -> 0 | FA2: =ER2-EZ2 -> 339360 | FB2: =ROUND(IF(FA2>0,IF(FA2>500000,12500,(FA2-250000)*0.05),0),0) -> 4468 | FC2: =IF(ROUND(IF(FA2>0,IF(FA2>1000000,25000,(FA2-500000)*0.2),0),0)<0,0,ROUND(IF(FA2>0,IF(FA2>1000000,25000,(FA2-500000)*0.2),0),0)) -> 0 | FD2: =FB2+FC2 -> 4468 | FE2: =IF(FD2<12500,0,FD2) -> 0 | FF2: =FE2*0.04 -> 0 | FG2: =ROUND(FF2+FE2,0) -> 0 | FH2: 0 | FI2: =FG2-FH2 -> 0 | FJ2: =IF(DY2>500000,TRUE,FALSE) -> FALSE | FK2: =IF(FJ2,RANDBETWEEN(500,1000),RANDBETWEEN(1000,3000)) -> 1341 | FL2: =DY2+FK2 -> 416501 | FM2: =IF(DY2>0,75000,0) -> 75000 | FN2: =FL2-FM2 -> 341501 | FO2: =IF(FN2>1500000,FN2-1500000,0) -> 0 | FP2: =FO2*0.3 -> 0 | FQ2: =IF(FN2>1200000,FN2-1200000-FO2,0) -> 0 | FR2: =FQ2*0.2 -> 0 | FS2: =IF(FN2>1000000,FN2-1000000-F2-FQ2,0) -> 0 | FT2: =FS2*0.15 -> 0 | FU2: =IF(FN2>700000,FN2-700000-FO2-FQ2-FS2,0) -> 0 | FV2: =FU2*0.1 -> 0 | FW2: =IF(FN2>300000,FN2-300000-FO2-FQ2-FS2-FU2,0) -> 41501 | FX2: =FW2*0.05 -> 2075.05 | FY2: =ROUND(FP2+FR2+FT2+FV2+FX2,0) -> 2075 | FZ2: =IF(FN2>700000,FN2,0) -> 0 | GA2: =IF(FN2>700000,FZ2-700000,0) -> 0 | GB2: =IF(FN2<700001,MIN(FY2,25000),0) -> 2075 | GC2: =IF(FN2>700000,FY2-GA2,0) -> 0 | GD2: =IF(GC2>0,TRUE,FALSE) -> FALSE | GE2: =IF(GD2,GC2,0) -> 0 | GF2: =GB2+GE2 -> 2075 | GG2: =ROUND(FY2-GF2,0) -> 0 | GH2: =GG2*0.04 -> 0 | GI2: =ROUNDUP(GG2+GH2,0) -> 0
A3: =_xlfn.AGGREGATE(3,5,$B$2:B3) -> 2 | B3: teachers102 | C3: MOUMITA MAJI | D3: AMORAGORI GIRLS PRIMARY SCHOOL | E3: WBTPTA | F3: 0 | G3: 6000 | H3: 29800 | I3: =H3*0.1 -> 2980 | J3: =H3*0.12 -> 3576 | K3: 0 | L3: 0 | M3: =SUM(H3:L3) -> 36356 | N3: 2000 | O3: 0 | P3: =IF($F3=50000,0,IF(M3>40000,200,IF(M3>25000,150,IF(M3>15000,130,IF(M3>10000,110,0))))) -> 150 | Q3: =M3-N3-O3-P3 -> 34206 | R3: 29800 | S3: =R3*0.1 -> 2980 | T3: =R3*0.12 -> 3576 | U3: 0 | V3: 0 | W3: =SUM(R3:V3) -> 36356 | X3: 2000 | Y3: 0 | Z3: =IF($F3=50000,0,IF(W3>40000,200,IF(W3>25000,150,IF(W3>15000,130,IF(W3>10000,110,0))))) -> 150 | AA3: =W3-X3-Y3-Z3 -> 34206 | AB3: 29800 | AC3: =AB3*0.14 -> 4172 | AD3: =AB3*0.12 -> 3576 | AE3: 0 | AF3: 0 | AG3: =SUM(AB3:AF3) -> 37548 | AH3: 2000 | AI3: 0 | AJ3: =IF($F3=50000,0,IF(AG3>40000,200,IF(AG3>25000,150,IF(AG3>15000,130,IF(AG3>10000,110,0))))) -> 150 | AK3: =AG3-AH3-AI3-AJ3 -> 35398 | AL3: 29800 | AM3: =AL3*0.14 -> 4172 | AN3: =AL3*0.12 -> 3576 | AO3: 0 | AP3: 0 | AQ3: =SUM(AL3:AP3) -> 37548 | AR3: 2000 | AS3: 0 | AT3: =IF($F3=50000,0,IF(AQ3>40000,200,IF(AQ3>25000,150,IF(AQ3>15000,130,IF(AQ3>10000,110,0))))) -> 150 | AU3: =AQ3-AR3-AS3-AT3 -> 35398 | AV3: 30700 | AW3: =AV3*0.14 -> 4298 | AX3: =R3*0.04 -> 1192 | AY3: =AV3*0.12 -> 3684 | AZ3: 0 | BA3: 0 | BB3: =SUM(AV3:BA3) -> 39874 | BC3: 2000 | BD3: 0 | BE3: =IF($F3=50000,0,IF(BB3>40000,200,IF(BB3>25000,150,IF(BB3>15000,130,IF(BB3>10000,110,0))))) -> 150 | BF3: =BB3-BC3-BD3-BE3 -> 37724 | BG3: 30700 | BH3: =BG3*0.14 -> 4298 | BI3: =BG3*0.12 -> 3684 | BJ3: 0 | BK3: 0 | BL3: =SUM(BG3:BK3) -> 38682 | BM3: 2000 | BN3: 0 | BO3: =IF($F3=50000,0,IF(BL3>40000,200,IF(BL3>25000,150,IF(BL3>15000,130,IF(BL3>10000,110,0))))) -> 150 | BP3: =BL3-BM3-BN3-BO3 -> 36532 | BQ3: 30700 | BR3: =BQ3*0.14 -> 4298 | BS3: =BQ3*0.12 -> 3684 | BT3: 0 | BU3: 0 | BV3: =SUM(BQ3:BU3) -> 38682 | BW3: 2000 | BX3: 0 | BY3: =IF($F3=50000,0,IF(BV3>40000,200,IF(BV3>25000,150,IF(BV3>15000,130,IF(BV3>10000,110,0))))) -> 150 | BZ3: =BV3-BW3-BX3-BY3 -> 36532 | CA3: 30700 | CB3: =CA3*0.14 -> 4298 | CC3: =CA3*0.12 -> 3684 | CD3: 0 | CE3: 0 | CF3: =SUM(CA3:CE3) -> 38682 | CG3: 2000 | CH3: 0 | CI3: =IF($F3=50000,0,IF(CF3>40000,200,IF(CF3>25000,150,IF(CF3>15000,130,IF(CF3>10000,110,0))))) -> 150 | CJ3: =CF3-CG3-CH3-CI3 -> 36532 | CK3: 30700 | CL3: =CK3*0.14 -> 4298 | CM3: =CK3*0.12 -> 3684 | CN3: 0 | CO3: 0 | CP3: =SUM(CK3:CO3) -> 38682 | CQ3: 2000 | CR3: 0 | CS3: =IF($F3=50000,0,IF(CP3>40000,200,IF(CP3>25000,150,IF(CP3>15000,130,IF(CP3>10000,110,0))))) -> 150 | CT3: =CP3-CQ3-CR3-CS3 -> 36532 | CU3: 30700 | CV3: =ROUND(CU3*0.14,0) -> 4298 | CW3: =ROUND(CU3*0.12,0) -> 3684 | CX3: 0 | CY3: 0 | CZ3: =SUM(CU3:CY3) -> 38682 | DA3: 2000 | DB3: 0 | DC3: =IF($F3=50000,0,IF(CZ3>40000,200,IF(CZ3>25000,150,IF(CZ3>15000,130,IF(CZ3>10000,110,0))))) -> 150 | DD3: =CZ3-DA3-DB3-DC3 -> 36532 | DE3: 30700 | DF3: =DE3*0.14 -> 4298 | DG3: =DE3*0.12 -> 3684 | DH3: 0 | DI3: 0 | DJ3: =SUM(DE3:DI3) -> 38682 | DK3: 2000 | DL3: 0 | DM3: =IF($F3=50000,0,IF(DJ3>40000,200,IF(DJ3>25000,150,IF(DJ3>15000,130,IF(DJ3>10000,110,0))))) -> 150 | DN3: =DJ3-DK3-DL3-DM3 -> 36532 | DO3: 30700 | DP3: =DO3*0.14 -> 4298 | DQ3: =DO3*0.12 -> 3684 | DR3: 0 | DS3: 0 | DT3: =SUM(DO3:DS3) -> 38682 | DU3: 2000 | DV3: 0 | DW3: =IF($F3=50000,0,IF(DT3>40000,200,IF(DT3>25000,150,IF(DT3>15000,130,IF(DT3>10000,110,0))))) -> 150 | DX3: =DT3-DU3-DV3-DW3 -> 36532 | DY3: =DT3+DJ3+CZ3+CP3+CF3+BV3+BL3+BB3+AQ3+AG3+W3+M3+G3 -> 464456 | DZ3: =DW3+DM3+DC3+CS3+CI3+BY3+BO3+BE3+AT3+AJ3+Z3+P3 -> 1800 | EA3: =IF(DY3>0,50000,0) -> 50000 | EB3: 0 | EC3: =DY3-DZ3-EA3 -> 412656 | ED3: =DU3+DK3+DA3+CQ3+CG3+BW3+BM3+BC3+AR3+AH3+X3+N3 -> 24000 | EE3: =DV3+DL3+DB3+CR3+CH3+BX3+BN3+BD3+AS3+AI3+Y3+O3 -> 0 | EF3: 0 | EG3: 0 | EH3: 0 | EI3: 0 | EJ3: 0 | EK3: 0 | EL3: 0 | EM3: 0 | EN3: 0 | EO3: 0 | EP3: =SUM(ED3:EO3) -> 24000 | EQ3: =IF(EP3>=150000,150000,EP3) -> 24000 | ER3: =EC3-EQ3 -> 388656 | ES3: 0 | ET3: 0 | EU3: 0 | EV3: 0 | EW3: 0 | EX3: 0 | EY3: 0 | EZ3: =SUM(ES3:EY3)+F3 -> 0 | FA3: =ER3-EZ3 -> 388656 | FB3: =ROUND(IF(FA3>0,IF(FA3>500000,12500,(FA3-250000)*0.05),0),0) -> 6933 | FC3: =IF(ROUND(IF(FA3>0,IF(FA3>1000000,25000,(FA3-500000)*0.2),0),0)<0,0,ROUND(IF(FA3>0,IF(FA3>1000000,25000,(FA3-500000)*0.2),0),0)) -> 0 | FD3: =FB3+FC3 -> 6933 | FE3: =IF(FD3<12500,0,FD3) -> 0 | FF3: =FE3*0.04 -> 0 | FG3: =ROUND(FF3+FE3,0) -> 0 | FH3: 0 | FI3: =FG3-FH3 -> 0 | FJ3: =IF(DY3>500000,TRUE,FALSE) -> FALSE | FK3: =IF(FJ3,RANDBETWEEN(500,1000),RANDBETWEEN(1000,3000)) -> 2705 | FL3: =DY3+FK3 -> 467161 | FM3: =IF(DY3>0,75000,0) -> 75000 | FN3: =FL3-FM3 -> 392161 | FO3: =IF(FN3>1500000,FN3-1500000,0) -> 0 | FP3: =FO3*0.3 -> 0 | FQ3: =IF(FN3>1200000,FN3-1200000-FO3,0) -> 0 | FR3: =FQ3*0.2 -> 0 | FS3: =IF(FN3>1000000,FN3-1000000-F3-FQ3,0) -> 0 | FT3: =FS3*0.15 -> 0 | FU3: =IF(FN3>700000,FN3-700000-FO3-FQ3-FS3,0) -> 0 | FV3: =FU3*0.1 -> 0 | FW3: =IF(FN3>300000,FN3-300000-FO3-FQ3-FS3-FU3,0) -> 92161 | FX3: =FW3*0.05 -> 4608.05 | FY3: =ROUND(FP3+FR3+FT3+FV3+FX3,0) -> 4608 | FZ3: =IF(FN3>700000,FN3,0) -> 0 | GA3: =IF(FN3>700000,FZ3-700000,0) -> 0 | GB3: =IF(FN3<700001,MIN(FY3,25000),0) -> 4608 | GC3: =IF(FN3>700000,FY3-GA3,0) -> 0 | GD3: =IF(GC3>0,TRUE,FALSE) -> FALSE | GE3: =IF(GD3,GC3,0) -> 0 | GF3: =GB3+GE3 -> 4608 | GG3: =ROUND(FY3-GF3,0) -> 0 | GH3: =GG3*0.04 -> 0 | GI3: =ROUNDUP(GG3+GH3,0) -> 0
A4: =_xlfn.AGGREGATE(3,5,$B$2:B4) -> 3 | B4: teachers103 | C4: RAGHABENDRA KOLEY | D4: BANCHARAM ROY PRIMARY SCHOOL | E4: WBTPTA | F4: 50000 | G4: 0 | H4: 45900 | I4: =H4*0.1 -> 4590 | J4: =H4*0.12 -> 5508 | K4: 0 | L4: 500 | M4: =SUM(H4:L4) -> 56498 | N4: 3000 | O4: 0 | P4: =IF($F4=50000,0,IF(M4>40000,200,IF(M4>25000,150,IF(M4>15000,130,IF(M4>10000,110,0))))) -> 0 | Q4: =M4-N4-O4-P4 -> 53498 | R4: 45900 | S4: =R4*0.1 -> 4590 | T4: =R4*0.12 -> 5508 | U4: 0 | V4: 500 | W4: =SUM(R4:V4) -> 56498 | X4: 3000 | Y4: 0 | Z4: =IF($F4=50000,0,IF(W4>40000,200,IF(W4>25000,150,IF(W4>15000,130,IF(W4>10000,110,0))))) -> 0 | AA4: =W4-X4-Y4-Z4 -> 53498 | AB4: 45900 | AC4: =AB4*0.14 -> 6426 | AD4: =AB4*0.12 -> 5508 | AE4: 0 | AF4: 500 | AG4: =SUM(AB4:AF4) -> 58334 | AH4: 3000 | AI4: 0 | AJ4: =IF($F4=50000,0,IF(AG4>40000,200,IF(AG4>25000,150,IF(AG4>15000,130,IF(AG4>10000,110,0))))) -> 0 | AK4: =AG4-AH4-AI4-AJ4 -> 55334 | AL4: 45900 | AM4: =AL4*0.14 -> 6426 | AN4: =AL4*0.12 -> 5508 | AO4: 0 | AP4: 500 | AQ4: =SUM(AL4:AP4) -> 58334 | AR4: 3000 | AS4: 0 | AT4: =IF($F4=50000,0,IF(AQ4>40000,200,IF(AQ4>25000,150,IF(AQ4>15000,130,IF(AQ4>10000,110,0))))) -> 0 | AU4: =AQ4-AR4-AS4-AT4 -> 55334 | AV4: 47300 | AW4: =AV4*0.14 -> 6622 | AX4: =R4*0.04 -> 1836 | AY4: =AV4*0.12 -> 5676 | AZ4: 0 | BA4: 500 | BB4: =SUM(AV4:BA4) -> 61934 | BC4: 3000 | BD4: 0 | BE4: =IF($F4=50000,0,IF(BB4>40000,200,IF(BB4>25000,150,IF(BB4>15000,130,IF(BB4>10000,110,0))))) -> 0 | BF4: =BB4-BC4-BD4-BE4 -> 58934 | BG4: 47300 | BH4: =BG4*0.14 -> 6622 | BI4: =BG4*0.12 -> 5676 | BJ4: 0 | BK4: 500 | BL4: =SUM(BG4:BK4) -> 60098 | BM4: 3000 | BN4: 0 | BO4: =IF($F4=50000,0,IF(BL4>40000,200,IF(BL4>25000,150,IF(BL4>15000,130,IF(BL4>10000,110,0))))) -> 0 | BP4: =BL4-BM4-BN4-BO4 -> 57098 | BQ4: 47300 | BR4: =BQ4*0.14 -> 6622 | BS4: =BQ4*0.12 -> 5676 | BT4: 0 | BU4: 500 | BV4: =SUM(BQ4:BU4) -> 60098 | BW4: 3000 | BX4: 0 | BY4: =IF($F4=50000,0,IF(BV4>40000,200,IF(BV4>25000,150,IF(BV4>15000,130,IF(BV4>10000,110,0))))) -> 0 | BZ4: =BV4-BW4-BX4-BY4 -> 57098 | CA4: 47300 | CB4: =CA4*0.14 -> 6622 | CC4: =CA4*0.12 -> 5676 | CD4: 0 | CE4: 500 | CF4: =SUM(CA4:CE4) -> 60098 | CG4: 3000 | CH4: 0 | CI4: =IF($F4=50000,0,IF(CF4>40000,200,IF(CF4>25000,150,IF(CF4>15000,130,IF(CF4>10000,110,0))))) -> 0 | CJ4: =CF4-CG4-CH4-CI4 -> 57098 | CK4: 47300 | CL4: =CK4*0.14 -> 6622 | CM4: =CK4*0.12 -> 5676 | CN4: 0 | CO4: 500 | CP4: =SUM(CK4:CO4) -> 60098 | CQ4: 3000 | CR4: 0 | CS4: =IF($F4=50000,0,IF(CP4>40000,200,IF(CP4>25000,150,IF(CP4>15000,130,IF(CP4>10000,110,0))))) -> 0 | CT4: =CP4-CQ4-CR4-CS4 -> 57098 | CU4: 47300 | CV4: =ROUND(CU4*0.14,0) -> 6622 | CW4: =ROUND(CU4*0.12,0) -> 5676 | CX4: 0 | CY4: 500 | CZ4: =SUM(CU4:CY4) -> 60098 | DA4: 3000 | DB4: 0 | DC4: =IF($F4=50000,0,IF(CZ4>40000,200,IF(CZ4>25000,150,IF(CZ4>15000,130,IF(CZ4>10000,110,0))))) -> 0 | DD4: =CZ4-DA4-DB4-DC4 -> 57098 | DE4: 47300 | DF4: =DE4*0.14 -> 6622 | DG4: =DE4*0.12 -> 5676 | DH4: 0 | DI4: 500 | DJ4: =SUM(DE4:DI4) -> 60098 | DK4: 3000 | DL4: 0 | DM4: =IF($F4=50000,0,IF(DJ4>40000,200,IF(DJ4>25000,150,IF(DJ4>15000,130,IF(DJ4>10000,110,0))))) -> 0 | DN4: =DJ4-DK4-DL4-DM4 -> 57098 | DO4: 47300 | DP4: =DO4*0.14 -> 6622 | DQ4: =DO4*0.12 -> 5676 | DR4: 0 | DS4: 500 | DT4: =SUM(DO4:DS4) -> 60098 | DU4: 3000 | DV4: 0 | DW4: =IF($F4=50000,0,IF(DT4>40000,200,IF(DT4>25000,150,IF(DT4>15000,130,IF(DT4>10000,110,0))))) -> 0 | DX4: =DT4-DU4-DV4-DW4 -> 57098 | DY4: =DT4+DJ4+CZ4+CP4+CF4+BV4+BL4+BB4+AQ4+AG4+W4+M4+G4 -> 712284 | DZ4: =DW4+DM4+DC4+CS4+CI4+BY4+BO4+BE4+AT4+AJ4+Z4+P4 -> 0 | EA4: =IF(DY4>0,50000,0) -> 50000 | EB4: 0 | EC4: =DY4-DZ4-EA4 -> 662284 | ED4: =DU4+DK4+DA4+CQ4+CG4+BW4+BM4+BC4+AR4+AH4+X4+N4 -> 36000 | EE4: =DV4+DL4+DB4+CR4+CH4+BX4+BN4+BD4+AS4+AI4+Y4+O4 -> 0 | EF4: 0 | EG4: 0 | EH4: 0 | EI4: 0 | EJ4: 0 | EK4: 0 | EL4: 0 | EM4: 0 | EN4: 0 | EO4: 0 | EP4: =SUM(ED4:EO4) -> 36000 | EQ4: =IF(EP4>=150000,150000,EP4) -> 36000 | ER4: =EC4-EQ4 -> 626284 | ES4: 0 | ET4: 0 | EU4: 0 | EV4: 0 | EW4: 0 | EX4: 0 | EY4: 0 | EZ4: =SUM(ES4:EY4)+F4 -> 50000 | FA4: =ER4-EZ4 -> 576284 | FB4: =ROUND(IF(FA4>0,IF(FA4>500000,12500,(FA4-250000)*0.05),0),0) -> 12500 | FC4: =IF(ROUND(IF(FA4>0,IF(FA4>1000000,25000,(FA4-500000)*0.2),0),0)<0,0,ROUND(IF(FA4>0,IF(FA4>1000000,25000,(FA4-500000)*0.2),0),0)) -> 15257 | FD4: =FB4+FC4 -> 27757 | FE4: =IF(FD4<12500,0,FD4) -> 27757 | FF4: =FE4*0.04 -> 1110.28 | FG4: =ROUND(FF4+FE4,0) -> 28867 | FH4: 0 | FI4: =FG4-FH4 -> 28867 | FJ4: =IF(DY4>500000,TRUE,FALSE) -> TRUE | FK4: =IF(FJ4,RANDBETWEEN(500,1000),RANDBETWEEN(1000,3000)) -> 543 | FL4: =DY4+FK4 -> 712827 | FM4: =IF(DY4>0,75000,0) -> 75000 | FN4: =FL4-FM4 -> 637827 | FO4: =IF(FN4>1500000,FN4-1500000,0) -> 0 | FP4: =FO4*0.3 -> 0 | FQ4: =IF(FN4>1200000,FN4-1200000-FO4,0) -> 0 | FR4: =FQ4*0.2 -> 0 | FS4: =IF(FN4>1000000,FN4-1000000-F4-FQ4,0) -> 0 | FT4: =FS4*0.15 -> 0 | FU4: =IF(FN4>700000,FN4-700000-FO4-FQ4-FS4,0) -> 0 | FV4: =FU4*0.1 -> 0 | FW4: =IF(FN4>300000,FN4-300000-FO4-FQ4-FS4-FU4,0) -> 337827 | FX4: =FW4*0.05 -> 16891.35 | FY4: =ROUND(FP4+FR4+FT4+FV4+FX4,0) -> 16891 | FZ4: =IF(FN4>700000,FN4,0) -> 0 | GA4: =IF(FN4>700000,FZ4-700000,0) -> 0 | GB4: =IF(FN4<700001,MIN(FY4,25000),0) -> 16891 | GC4: =IF(FN4>700000,FY4-GA4,0) -> 0 | GD4: =IF(GC4>0,TRUE,FALSE) -> FALSE | GE4: =IF(GD4,GC4,0) -> 0 | GF4: =GB4+GE4 -> 16891 | GG4: =ROUND(FY4-GF4,0) -> 0 | GH4: =GG4*0.04 -> 0 | GI4: =ROUNDUP(GG4+GH4,0) -> 0
A5: =_xlfn.AGGREGATE(3,5,$B$2:B5) -> 4 | B5: teachers104 | C5: AVISHEK CHOWDHURY | D5: BANCHARAM ROY PRIMARY SCHOOL | E5: WBTPTA | F5: 0 | G5: 0 | H5: 24700 | I5: =H5*0.1 -> 2470 | J5: =H5*0.12 -> 2964 | K5: 0 | L5: 500 | M5: =SUM(H5:L5) -> 30634 | N5: 0 | O5: 0 | P5: =IF($F5=50000,0,IF(M5>40000,200,IF(M5>25000,150,IF(M5>15000,130,IF(M5>10000,110,0))))) -> 150 | Q5: =M5-N5-O5-P5 -> 30484 | R5: 24700 | S5: =R5*0.1 -> 2470 | T5: =R5*0.12 -> 2964 | U5: 0 | V5: 500 | W5: =SUM(R5:V5) -> 30634 | X5: 0 | Y5: 0 | Z5: =IF($F5=50000,0,IF(W5>40000,200,IF(W5>25000,150,IF(W5>15000,130,IF(W5>10000,110,0))))) -> 150 | AA5: =W5-X5-Y5-Z5 -> 30484 | AB5: 24700 | AC5: =AB5*0.14 -> 3458 | AD5: =AB5*0.12 -> 2964 | AE5: 0 | AF5: 500 | AG5: =SUM(AB5:AF5) -> 31622 | AH5: 0 | AI5: 0 | AJ5: =IF($F5=50000,0,IF(AG5>40000,200,IF(AG5>25000,150,IF(AG5>15000,130,IF(AG5>10000,110,0))))) -> 150 | AK5: =AG5-AH5-AI5-AJ5 -> 31472 | AL5: 24700 | AM5: =AL5*0.14 -> 3458 | AN5: =AL5*0.12 -> 2964 | AO5: 0 | AP5: 500 | AQ5: =SUM(AL5:AP5) -> 31622 | AR5: 0 | AS5: 0 | AT5: =IF($F5=50000,0,IF(AQ5>40000,200,IF(AQ5>25000,150,IF(AQ5>15000,130,IF(AQ5>10000,110,0))))) -> 150 | AU5: =AQ5-AR5-AS5-AT5 -> 31472 | AV5: 25400 | AW5: =AV5*0.14 -> 3556 | AX5: =R5*0.04 -> 988 | AY5: =AV5*0.12 -> 3048 | AZ5: 0 | BA5: 500 | BB5: =SUM(AV5:BA5) -> 33492 | BC5: 0 | BD5: 0 | BE5: =IF($F5=50000,0,IF(BB5>40000,200,IF(BB5>25000,150,IF(BB5>15000,130,IF(BB5>10000,110,0))))) -> 150 | BF5: =BB5-BC5-BD5-BE5 -> 33342 | BG5: 25400 | BH5: =BG5*0.14 -> 3556 | BI5: =BG5*0.12 -> 3048 | BJ5: 0 | BK5: 500 | BL5: =SUM(BG5:BK5) -> 32504 | BM5: 0 | BN5: 0 | BO5: =IF($F5=50000,0,IF(BL5>40000,200,IF(BL5>25000,150,IF(BL5>15000,130,IF(BL5>10000,110,0))))) -> 150 | BP5: =BL5-BM5-BN5-BO5 -> 32354 | BQ5: 25400 | BR5: =BQ5*0.14 -> 3556 | BS5: =BQ5*0.12 -> 3048 | BT5: 0 | BU5: 500 | BV5: =SUM(BQ5:BU5) -> 32504 | BW5: 0 | BX5: 0 | BY5: =IF($F5=50000,0,IF(BV5>40000,200,IF(BV5>25000,150,IF(BV5>15000,130,IF(BV5>10000,110,0))))) -> 150 | BZ5: =BV5-BW5-BX5-BY5 -> 32354 | CA5: 25400 | CB5: =CA5*0.14 -> 3556 | CC5: =CA5*0.12 -> 3048 | CD5: 0 | CE5: 500 | CF5: =SUM(CA5:CE5) -> 32504 | CG5: 0 | CH5: 0 | CI5: =IF($F5=50000,0,IF(CF5>40000,200,IF(CF5>25000,150,IF(CF5>15000,130,IF(CF5>10000,110,0))))) -> 150 | CJ5: =CF5-CG5-CH5-CI5 -> 32354 | CK5: 25400 | CL5: =CK5*0.14 -> 3556 | CM5: =CK5*0.12 -> 3048 | CN5: 0 | CO5: 500 | CP5: =SUM(CK5:CO5) -> 32504 | CQ5: 2000 | CR5: 0 | CS5: =IF($F5=50000,0,IF(CP5>40000,200,IF(CP5>25000,150,IF(CP5>15000,130,IF(CP5>10000,110,0))))) -> 150 | CT5: =CP5-CQ5-CR5-CS5 -> 30354 | CU5: 25400 | CV5: =ROUND(CU5*0.14,0) -> 3556 | CW5: =ROUND(CU5*0.12,0) -> 3048 | CX5: 0 | CY5: 500 | CZ5: =SUM(CU5:CY5) -> 32504 | DA5: 2000 | DB5: 0 | DC5: =IF($F5=50000,0,IF(CZ5>40000,200,IF(CZ5>25000,150,IF(CZ5>15000,130,IF(CZ5>10000,110,0))))) -> 150 | DD5: =CZ5-DA5-DB5-DC5 -> 30354 | DE5: 25400 | DF5: =DE5*0.14 -> 3556 | DG5: =DE5*0.12 -> 3048 | DH5: 0 | DI5: 500 | DJ5: =SUM(DE5:DI5) -> 32504 | DK5: 2000 | DL5: 0 | DM5: =IF($F5=50000,0,IF(DJ5>40000,200,IF(DJ5>25000,150,IF(DJ5>15000,130,IF(DJ5>10000,110,0))))) -> 150 | DN5: =DJ5-DK5-DL5-DM5 -> 30354 | DO5: 25400 | DP5: =DO5*0.14 -> 3556 | DQ5: =DO5*0.12 -> 3048 | DR5: 0 | DS5: 500 | DT5: =SUM(DO5:DS5) -> 32504 | DU5: 2000 | DV5: 0 | DW5: =IF($F5=50000,0,IF(DT5>40000,200,IF(DT5>25000,150,IF(DT5>15000,130,IF(DT5>10000,110,0))))) -> 150 | DX5: =DT5-DU5-DV5-DW5 -> 30354 | DY5: =DT5+DJ5+CZ5+CP5+CF5+BV5+BL5+BB5+AQ5+AG5+W5+M5+G5 -> 385532 | DZ5: =DW5+DM5+DC5+CS5+CI5+BY5+BO5+BE5+AT5+AJ5+Z5+P5 -> 1800 | EA5: =IF(DY5>0,50000,0) -> 50000 | EB5: 0 | EC5: =DY5-DZ5-EA5 -> 333732 | ED5: =DU5+DK5+DA5+CQ5+CG5+BW5+BM5+BC5+AR5+AH5+X5+N5 -> 8000 | EE5: =DV5+DL5+DB5+CR5+CH5+BX5+BN5+BD5+AS5+AI5+Y5+O5 -> 0 | EF5: 0 | EG5: 0 | EH5: 0 | EI5: 0 | EJ5: 0 | EK5: 0 | EL5: 0 | EM5: 0 | EN5: 0 | EO5: 0 | EP5: =SUM(ED5:EO5) -> 8000 | EQ5: =IF(EP5>=150000,150000,EP5) -> 8000 | ER5: =EC5-EQ5 -> 325732 | ES5: 0 | ET5: 0 | EU5: 0 | EV5: 0 | EW5: 0 | EX5: 0 | EY5: 0 | EZ5: =SUM(ES5:EY5)+F5 -> 0 | FA5: =ER5-EZ5 -> 325732 | FB5: =ROUND(IF(FA5>0,IF(FA5>500000,12500,(FA5-250000)*0.05),0),0) -> 3787 | FC5: =IF(ROUND(IF(FA5>0,IF(FA5>1000000,25000,(FA5-500000)*0.2),0),0)<0,0,ROUND(IF(FA5>0,IF(FA5>1000000,25000,(FA5-500000)*0.2),0),0)) -> 0 | FD5: =FB5+FC5 -> 3787 | FE5: =IF(FD5<12500,0,FD5) -> 0 | FF5: =FE5*0.04 -> 0 | FG5: =ROUND(FF5+FE5,0) -> 0 | FH5: 0 | FI5: =FG5-FH5 -> 0 | FJ5: =IF(DY5>500000,TRUE,FALSE) -> FALSE | FK5: =IF(FJ5,RANDBETWEEN(500,1000),RANDBETWEEN(1000,3000)) -> 1327 | FL5: =DY5+FK5 -> 386859 | FM5: =IF(DY5>0,75000,0) -> 75000 | FN5: =FL5-FM5 -> 311859 | FO5: =IF(FN5>1500000,FN5-1500000,0) -> 0 | FP5: =FO5*0.3 -> 0 | FQ5: =IF(FN5>1200000,FN5-1200000-FO5,0) -> 0 | FR5: =FQ5*0.2 -> 0 | FS5: =IF(FN5>1000000,FN5-1000000-F5-FQ5,0) -> 0 | FT5: =FS5*0.15 -> 0 | FU5: =IF(FN5>700000,FN5-700000-FO5-FQ5-FS5,0) -> 0 | FV5: =FU5*0.1 -> 0 | FW5: =IF(FN5>300000,FN5-300000-FO5-FQ5-FS5-FU5,0) -> 11859 | FX5: =FW5*0.05 -> 592.95 | FY5: =ROUND(FP5+FR5+FT5+FV5+FX5,0) -> 593 | FZ5: =IF(FN5>700000,FN5,0) -> 0 | GA5: =IF(FN5>700000,FZ5-700000,0) -> 0 | GB5: =IF(FN5<700001,MIN(FY5,25000),0) -> 593 | GC5: =IF(FN5>700000,FY5-GA5,0) -> 0 | GD5: =IF(GC5>0,TRUE,FALSE) -> FALSE | GE5: =IF(GD5,GC5,0) -> 0 | GF5: =GB5+GE5 -> 593 | GG5: =ROUND(FY5-GF5,0) -> 0 | GH5: =GG5*0.04 -> 0 | GI5: =ROUNDUP(GG5+GH5,0) -> 0
A6: =_xlfn.AGGREGATE(3,5,$B$2:B6) -> 5 | B6: teachers105 | C6: AMIT RIT | D6: BAR GAZIPUR PRIMARY SCHOOL | E6: ABPTA | F6: 0 | G6: 6000 | H6: 32500 | I6: =H6*0.1 -> 3250 | J6: =H6*0.12 -> 3900 | K6: 400 | L6: 500 | M6: =SUM(H6:L6) -> 40550 | N6: 4000 | O6: 0 | P6: =IF($F6=50000,0,IF(M6>40000,200,IF(M6>25000,150,IF(M6>15000,130,IF(M6>10000,110,0))))) -> 200 | Q6: =M6-N6-O6-P6 -> 36350 | R6: 32500 | S6: =R6*0.1 -> 3250 | T6: =R6*0.12 -> 3900 | U6: 400 | V6: 500 | W6: =SUM(R6:V6) -> 40550 | X6: 4000 | Y6: 0 | Z6: =IF($F6=50000,0,IF(W6>40000,200,IF(W6>25000,150,IF(W6>15000,130,IF(W6>10000,110,0))))) -> 200 | AA6: =W6-X6-Y6-Z6 -> 36350 | AB6: 32500 | AC6: =AB6*0.14 -> 4550 | AD6: =AB6*0.12 -> 3900 | AE6: 400 | AF6: 500 | AG6: =SUM(AB6:AF6) -> 41850 | AH6: 4000 | AI6: 0 | AJ6: =IF($F6=50000,0,IF(AG6>40000,200,IF(AG6>25000,150,IF(AG6>15000,130,IF(AG6>10000,110,0))))) -> 200 | AK6: =AG6-AH6-AI6-AJ6 -> 37650 | AL6: 32500 | AM6: =AL6*0.14 -> 4550 | AN6: =AL6*0.12 -> 3900 | AO6: 400 | AP6: 500 | AQ6: =SUM(AL6:AP6) -> 41850 | AR6: 4000 | AS6: 0 | AT6: =IF($F6=50000,0,IF(AQ6>40000,200,IF(AQ6>25000,150,IF(AQ6>15000,130,IF(AQ6>10000,110,0))))) -> 200 | AU6: =AQ6-AR6-AS6-AT6 -> 37650 | AV6: 34500 | AW6: =AV6*0.14 -> 4830 | AX6: =R6*0.04 -> 1300 | AY6: =AV6*0.12 -> 4140 | AZ6: 400 | BA6: 500 | BB6: =SUM(AV6:BA6) -> 45670 | BC6: 4000 | BD6: 0 | BE6: =IF($F6=50000,0,IF(BB6>40000,200,IF(BB6>25000,150,IF(BB6>15000,130,IF(BB6>10000,110,0))))) -> 200 | BF6: =BB6-BC6-BD6-BE6 -> 41470 | BG6: 34500 | BH6: =BG6*0.14 -> 4830 | BI6: =BG6*0.12 -> 4140 | BJ6: 400 | BK6: 500 | BL6: =SUM(BG6:BK6) -> 44370 | BM6: 4000 | BN6: 0 | BO6: =IF($F6=50000,0,IF(BL6>40000,200,IF(BL6>25000,150,IF(BL6>15000,130,IF(BL6>10000,110,0))))) -> 200 | BP6: =BL6-BM6-BN6-BO6 -> 40170 | BQ6: 34500 | BR6: =BQ6*0.14 -> 4830 | BS6: =BQ6*0.12 -> 4140 | BT6: 400 | BU6: 500 | BV6: =SUM(BQ6:BU6) -> 44370 | BW6: 4000 | BX6: 0 | BY6: =IF($F6=50000,0,IF(BV6>40000,200,IF(BV6>25000,150,IF(BV6>15000,130,IF(BV6>10000,110,0))))) -> 200 | BZ6: =BV6-BW6-BX6-BY6 -> 40170 | CA6: 34500 | CB6: =CA6*0.14 -> 4830 | CC6: =CA6*0.12 -> 4140 | CD6: 400 | CE6: 500 | CF6: =SUM(CA6:CE6) -> 44370 | CG6: 4000 | CH6: 0 | CI6: =IF($F6=50000,0,IF(CF6>40000,200,IF(CF6>25000,150,IF(CF6>15000,130,IF(CF6>10000,110,0))))) -> 200 | CJ6: =CF6-CG6-CH6-CI6 -> 40170 | CK6: 34500 | CL6: =CK6*0.14 -> 4830 | CM6: =CK6*0.12 -> 4140 | CN6: 400 | CO6: 500 | CP6: =SUM(CK6:CO6) -> 44370 | CQ6: 4000 | CR6: 0 | CS6: =IF($F6=50000,0,IF(CP6>40000,200,IF(CP6>25000,150,IF(CP6>15000,130,IF(CP6>10000,110,0))))) -> 200 | CT6: =CP6-CQ6-CR6-CS6 -> 40170 | CU6: 34500 | CV6: =ROUND(CU6*0.14,0) -> 4830 | CW6: =ROUND(CU6*0.12,0) -> 4140 | CX6: 400 | CY6: 500 | CZ6: =SUM(CU6:CY6) -> 44370 | DA6: 4000 | DB6: 0 | DC6: =IF($F6=50000,0,IF(CZ6>40000,200,IF(CZ6>25000,150,IF(CZ6>15000,130,IF(CZ6>10000,110,0))))) -> 200 | DD6: =CZ6-DA6-DB6-DC6 -> 40170 | DE6: 34500 | DF6: =DE6*0.14 -> 4830 | DG6: =DE6*0.12 -> 4140 | DH6: 400 | DI6: 500 | DJ6: =SUM(DE6:DI6) -> 44370 | DK6: 4000 | DL6: 0 | DM6: =IF($F6=50000,0,IF(DJ6>40000,200,IF(DJ6>25000,150,IF(DJ6>15000,130,IF(DJ6>10000,110,0))))) -> 200 | DN6: =DJ6-DK6-DL6-DM6 -> 40170 | DO6: 34500 | DP6: =DO6*0.14 -> 4830 | DQ6: =DO6*0.12 -> 4140 | DR6: 400 | DS6: 500 | DT6: =SUM(DO6:DS6) -> 44370 | DU6: 4000 | DV6: 0 | DW6: =IF($F6=50000,0,IF(DT6>40000,200,IF(DT6>25000,150,IF(DT6>15000,130,IF(DT6>10000,110,0))))) -> 200 | DX6: =DT6-DU6-DV6-DW6 -> 40170 | DY6: =DT6+DJ6+CZ6+CP6+CF6+BV6+BL6+BB6+AQ6+AG6+W6+M6+G6 -> 527060 | DZ6: =DW6+DM6+DC6+CS6+CI6+BY6+BO6+BE6+AT6+AJ6+Z6+P6 -> 2400 | EA6: =IF(DY6>0,50000,0) -> 50000 | EB6: 0 | EC6: =DY6-DZ6-EA6 -> 474660 | ED6: =DU6+DK6+DA6+CQ6+CG6+BW6+BM6+BC6+AR6+AH6+X6+N6 -> 48000 | EE6: =DV6+DL6+DB6+CR6+CH6+BX6+BN6+BD6+AS6+AI6+Y6+O6 -> 0 | EF6: 0 | EG6: 0 | EH6: 0 | EI6: 0 | EJ6: 0 | EK6: 0 | EL6: 0 | EM6: 0 | EN6: 0 | EO6: 0 | EP6: =SUM(ED6:EO6) -> 48000 | EQ6: =IF(EP6>=150000,150000,EP6) -> 48000 | ER6: =EC6-EQ6 -> 426660 | ES6: 0 | ET6: 0 | EU6: 0 | EV6: 0 | EW6: 0 | EX6: 0 | EY6: 0 | EZ6: =SUM(ES6:EY6)+F6 -> 0 | FA6: =ER6-EZ6 -> 426660 | FB6: =ROUND(IF(FA6>0,IF(FA6>500000,12500,(FA6-250000)*0.05),0),0) -> 8833 | FC6: =IF(ROUND(IF(FA6>0,IF(FA6>1000000,25000,(FA6-500000)*0.2),0),0)<0,0,ROUND(IF(FA6>0,IF(FA6>1000000,25000,(FA6-500000)*0.2),0),0)) -> 0 | FD6: =FB6+FC6 -> 8833 | FE6: =IF(FD6<12500,0,FD6) -> 0 | FF6: =FE6*0.04 -> 0 | FG6: =ROUND(FF6+FE6,0) -> 0 | FH6: 0 | FI6: =FG6-FH6 -> 0 | FJ6: =IF(DY6>500000,TRUE,FALSE) -> TRUE | FK6: =IF(FJ6,RANDBETWEEN(500,1000),RANDBETWEEN(1000,3000)) -> 925 | FL6: =DY6+FK6 -> 527985 | FM6: =IF(DY6>0,75000,0) -> 75000 | FN6: =FL6-FM6 -> 452985 | FO6: =IF(FN6>1500000,FN6-1500000,0) -> 0 | FP6: =FO6*0.3 -> 0 | FQ6: =IF(FN6>1200000,FN6-1200000-FO6,0) -> 0 | FR6: =FQ6*0.2 -> 0 | FS6: =IF(FN6>1000000,FN6-1000000-F6-FQ6,0) -> 0 | FT6: =FS6*0.15 -> 0 | FU6: =IF(FN6>700000,FN6-700000-FO6-FQ6-FS6,0) -> 0 | FV6: =FU6*0.1 -> 0 | FW6: =IF(FN6>300000,FN6-300000-FO6-FQ6-FS6-FU6,0) -> 152985 | FX6: =FW6*0.05 -> 7649.25 | FY6: =ROUND(FP6+FR6+FT6+FV6+FX6,0) -> 7649 | FZ6: =IF(FN6>700000,FN6,0) -> 0 | GA6: =IF(FN6>700000,FZ6-700000,0) -> 0 | GB6: =IF(FN6<700001,MIN(FY6,25000),0) -> 7649 | GC6: =IF(FN6>700000,FY6-GA6,0) -> 0 | GD6: =IF(GC6>0,TRUE,FALSE) -> FALSE | GE6: =IF(GD6,GC6,0) -> 0 | GF6: =GB6+GE6 -> 7649 | GG6: =ROUND(FY6-GF6,0) -> 0 | GH6: =GG6*0.04 -> 0 | GI6: =ROUNDUP(GG6+GH6,0) -> 0
A7: =_xlfn.AGGREGATE(3,5,$B$2:B7) -> 6 | B7: teachers106 | C7: TAPAS KARMAKAR | D7: BAR GAZIPUR PRIMARY SCHOOL | E7: WBTPTA | F7: 0 | G7: 6000 | H7: 26200 | I7: =H7*0.1 -> 2620 | J7: =H7*0.12 -> 3144 | K7: 0 | L7: 500 | M7: =SUM(H7:L7) -> 32464 | N7: 2000 | O7: 0 | P7: =IF($F7=50000,0,IF(M7>40000,200,IF(M7>25000,150,IF(M7>15000,130,IF(M7>10000,110,0))))) -> 150 | Q7: =M7-N7-O7-P7 -> 30314 | R7: 26200 | S7: =R7*0.1 -> 2620 | T7: =R7*0.12 -> 3144 | U7: 0 | V7: 500 | W7: =SUM(R7:V7) -> 32464 | X7: 2000 | Y7: 0 | Z7: =IF($F7=50000,0,IF(W7>40000,200,IF(W7>25000,150,IF(W7>15000,130,IF(W7>10000,110,0))))) -> 150 | AA7: =W7-X7-Y7-Z7 -> 30314 | AB7: 26200 | AC7: =AB7*0.14 -> 3668 | AD7: =AB7*0.12 -> 3144 | AE7: 0 | AF7: 500 | AG7: =SUM(AB7:AF7) -> 33512 | AH7: 2000 | AI7: 0 | AJ7: =IF($F7=50000,0,IF(AG7>40000,200,IF(AG7>25000,150,IF(AG7>15000,130,IF(AG7>10000,110,0))))) -> 150 | AK7: =AG7-AH7-AI7-AJ7 -> 31362 | AL7: 26200 | AM7: =AL7*0.14 -> 3668 | AN7: =AL7*0.12 -> 3144 | AO7: 0 | AP7: 500 | AQ7: =SUM(AL7:AP7) -> 33512 | AR7: 2000 | AS7: 0 | AT7: =IF($F7=50000,0,IF(AQ7>40000,200,IF(AQ7>25000,150,IF(AQ7>15000,130,IF(AQ7>10000,110,0))))) -> 150 | AU7: =AQ7-AR7-AS7-AT7 -> 31362 | AV7: 27000 | AW7: =AV7*0.14 -> 3780 | AX7: =R7*0.04 -> 1048 | AY7: =AV7*0.12 -> 3240 | AZ7: 0 | BA7: 500 | BB7: =SUM(AV7:BA7) -> 35568 | BC7: 2000 | BD7: 0 | BE7: =IF($F7=50000,0,IF(BB7>40000,200,IF(BB7>25000,150,IF(BB7>15000,130,IF(BB7>10000,110,0))))) -> 150 | BF7: =BB7-BC7-BD7-BE7 -> 33418 | BG7: 27000 | BH7: =BG7*0.14 -> 3780 | BI7: =BG7*0.12 -> 3240 | BJ7: 0 | BK7: 500 | BL7: =SUM(BG7:BK7) -> 34520 | BM7: 2000 | BN7: 0 | BO7: =IF($F7=50000,0,IF(BL7>40000,200,IF(BL7>25000,150,IF(BL7>15000,130,IF(BL7>10000,110,0))))) -> 150 | BP7: =BL7-BM7-BN7-BO7 -> 32370 | BQ7: 27000 | BR7: =BQ7*0.14 -> 3780 | BS7: =BQ7*0.12 -> 3240 | BT7: 0 | BU7: 500 | BV7: =SUM(BQ7:BU7) -> 34520 | BW7: 2000 | BX7: 0 | BY7: =IF($F7=50000,0,IF(BV7>40000,200,IF(BV7>25000,150,IF(BV7>15000,130,IF(BV7>10000,110,0))))) -> 150 | BZ7: =BV7-BW7-BX7-BY7 -> 32370 | CA7: 27000 | CB7: =CA7*0.14 -> 3780 | CC7: =CA7*0.12 -> 3240 | CD7: 0 | CE7: 500 | CF7: =SUM(CA7:CE7) -> 34520 | CG7: 2000 | CH7: 0 | CI7: =IF($F7=50000,0,IF(CF7>40000,200,IF(CF7>25000,150,IF(CF7>15000,130,IF(CF7>10000,110,0))))) -> 150 | CJ7: =CF7-CG7-CH7-CI7 -> 32370 | CK7: 27000 | CL7: =CK7*0.14 -> 3780 | CM7: =CK7*0.12 -> 3240 | CN7: 0 | CO7: 500 | CP7: =SUM(CK7:CO7) -> 34520 | CQ7: 2000 | CR7: 0 | CS7: =IF($F7=50000,0,IF(CP7>40000,200,IF(CP7>25000,150,IF(CP7>15000,130,IF(CP7>10000,110,0))))) -> 150 | CT7: =CP7-CQ7-CR7-CS7 -> 32370 | CU7: 27000 | CV7: =ROUND(CU7*0.14,0) -> 3780 | CW7: =ROUND(CU7*0.12,0) -> 3240 | CX7: 0 | CY7: 500 | CZ7: =SUM(CU7:CY7) -> 34520 | DA7: 2000 | DB7: 0 | DC7: =IF($F7=50000,0,IF(CZ7>40000,200,IF(CZ7>25000,150,IF(CZ7>15000,130,IF(CZ7>10000,110,0))))) -> 150 | DD7: =CZ7-DA7-DB7-DC7 -> 32370 | DE7: 27000 | DF7: =DE7*0.14 -> 3780 | DG7: =DE7*0.12 -> 3240 | DH7: 0 | DI7: 500 | DJ7: =SUM(DE7:DI7) -> 34520 | DK7: 2000 | DL7: 0 | DM7: =IF($F7=50000,0,IF(DJ7>40000,200,IF(DJ7>25000,150,IF(DJ7>15000,130,IF(DJ7>10000,110,0))))) -> 150 | DN7: =DJ7-DK7-DL7-DM7 -> 32370 | DO7: 27000 | DP7: =DO7*0.14 -> 3780 | DQ7: =DO7*0.12 -> 3240 | DR7: 0 | DS7: 500 | DT7: =SUM(DO7:DS7) -> 34520 | DU7: 2000 | DV7: 0 | DW7: =IF($F7=50000,0,IF(DT7>40000,200,IF(DT7>25000,150,IF(DT7>15000,130,IF(DT7>10000,110,0))))) -> 150 | DX7: =DT7-DU7-DV7-DW7 -> 32370 | DY7: =DT7+DJ7+CZ7+CP7+CF7+BV7+BL7+BB7+AQ7+AG7+W7+M7+G7 -> 415160 | DZ7: =DW7+DM7+DC7+CS7+CI7+BY7+BO7+BE7+AT7+AJ7+Z7+P7 -> 1800 | EA7: =IF(DY7>0,50000,0) -> 50000 | EB7: 0 | EC7: =DY7-DZ7-EA7 -> 363360 | ED7: =DU7+DK7+DA7+CQ7+CG7+BW7+BM7+BC7+AR7+AH7+X7+N7 -> 24000 | EE7: =DV7+DL7+DB7+CR7+CH7+BX7+BN7+BD7+AS7+AI7+Y7+O7 -> 0 | EF7: 0 | EG7: 0 | EH7: 0 | EI7: 0 | EJ7: 0 | EK7: 0 | EL7: 0 | EM7: 0 | EN7: 0 | EO7: 0 | EP7: =SUM(ED7:EO7) -> 24000 | EQ7: =IF(EP7>=150000,150000,EP7) -> 24000 | ER7: =EC7-EQ7 -> 339360 | ES7: 0 | ET7: 0 | EU7: 0 | EV7: 0 | EW7: 0 | EX7: 0 | EY7: 0 | EZ7: =SUM(ES7:EY7)+F7 -> 0 | FA7: =ER7-EZ7 -> 339360 | FB7: =ROUND(IF(FA7>0,IF(FA7>500000,12500,(FA7-250000)*0.05),0),0) -> 4468 | FC7: =IF(ROUND(IF(FA7>0,IF(FA7>1000000,25000,(FA7-500000)*0.2),0),0)<0,0,ROUND(IF(FA7>0,IF(FA7>1000000,25000,(FA7-500000)*0.2),0),0)) -> 0 | FD7: =FB7+FC7 -> 4468 | FE7: =IF(FD7<12500,0,FD7) -> 0 | FF7: =FE7*0.04 -> 0 | FG7: =ROUND(FF7+FE7,0) -> 0 | FH7: 0 | FI7: =FG7-FH7 -> 0 | FJ7: =IF(DY7>500000,TRUE,FALSE) -> FALSE | FK7: =IF(FJ7,RANDBETWEEN(500,1000),RANDBETWEEN(1000,3000)) -> 2295 | FL7: =DY7+FK7 -> 417455 | FM7: =IF(DY7>0,75000,0) -> 75000 | FN7: =FL7-FM7 -> 342455 | FO7: =IF(FN7>1500000,FN7-1500000,0) -> 0 | FP7: =FO7*0.3 -> 0 | FQ7: =IF(FN7>1200000,FN7-1200000-FO7,0) -> 0 | FR7: =FQ7*0.2 -> 0 | FS7: =IF(FN7>1000000,FN7-1000000-F7-FQ7,0) -> 0 | FT7: =FS7*0.15 -> 0 | FU7: =IF(FN7>700000,FN7-700000-FO7-FQ7-FS7,0) -> 0 | FV7: =FU7*0.1 -> 0 | FW7: =IF(FN7>300000,FN7-300000-FO7-FQ7-FS7-FU7,0) -> 42455 | FX7: =FW7*0.05 -> 2122.75 | FY7: =ROUND(FP7+FR7+FT7+FV7+FX7,0) -> 2123 | FZ7: =IF(FN7>700000,FN7,0) -> 0 | GA7: =IF(FN7>700000,FZ7-700000,0) -> 0 | GB7: =IF(FN7<700001,MIN(FY7,25000),0) -> 2123 | GC7: =IF(FN7>700000,FY7-GA7,0) -> 0 | GD7: =IF(GC7>0,TRUE,FALSE) -> FALSE | GE7: =IF(GD7,GC7,0) -> 0 | GF7: =GB7+GE7 -> 2123 | GG7: =ROUND(FY7-GF7,0) -> 0 | GH7: =GG7*0.04 -> 0 | GI7: =ROUNDUP(GG7+GH7,0) -> 0
A8: =_xlfn.AGGREGATE(3,5,$B$2:B8) -> 7 | B8: teachers107 | C8: BIKASH CHANDRA DALUI | D8: BER DHAIPUR PRIMARY SCHOOL | E8: WBPTA | F8: 0 | G8: 0 | H8: 45900 | I8: =H8*0.1 -> 4590 | J8: =H8*0.12 -> 5508 | K8: 400 | L8: 500 | M8: =SUM(H8:L8) -> 56898 | N8: 3000 | O8: 0 | P8: =IF($F8=50000,0,IF(M8>40000,200,IF(M8>25000,150,IF(M8>15000,130,IF(M8>10000,110,0))))) -> 200 | Q8: =M8-N8-O8-P8 -> 53698 | R8: 45900 | S8: =R8*0.1 -> 4590 | T8: =R8*0.12 -> 5508 | U8: 400 | V8: 500 | W8: =SUM(R8:V8) -> 56898 | X8: 3000 | Y8: 0 | Z8: =IF($F8=50000,0,IF(W8>40000,200,IF(W8>25000,150,IF(W8>15000,130,IF(W8>10000,110,0))))) -> 200 | AA8: =W8-X8-Y8-Z8 -> 53698 | AB8: 45900 | AC8: =AB8*0.14 -> 6426 | AD8: =AB8*0.12 -> 5508 | AE8: 400 | AF8: 500 | AG8: =SUM(AB8:AF8) -> 58734 | AH8: 3000 | AI8: 0 | AJ8: =IF($F8=50000,0,IF(AG8>40000,200,IF(AG8>25000,150,IF(AG8>15000,130,IF(AG8>10000,110,0))))) -> 200 | AK8: =AG8-AH8-AI8-AJ8 -> 55534 | AL8: 45900 | AM8: =AL8*0.14 -> 6426 | AN8: =AL8*0.12 -> 5508 | AO8: 400 | AP8: 500 | AQ8: =SUM(AL8:AP8) -> 58734 | AR8: 3000 | AS8: 0 | AT8: =IF($F8=50000,0,IF(AQ8>40000,200,IF(AQ8>25000,150,IF(AQ8>15000,130,IF(AQ8>10000,110,0))))) -> 200 | AU8: =AQ8-AR8-AS8-AT8 -> 55534 | AV8: 47300 | AW8: =AV8*0.14 -> 6622 | AX8: =R8*0.04 -> 1836 | AY8: =AV8*0.12 -> 5676 | AZ8: 400 | BA8: 500 | BB8: =SUM(AV8:BA8) -> 62334 | BC8: 3000 | BD8: 0 | BE8: =IF($F8=50000,0,IF(BB8>40000,200,IF(BB8>25000,150,IF(BB8>15000,130,IF(BB8>10000,110,0))))) -> 200 | BF8: =BB8-BC8-BD8-BE8 -> 59134 | BG8: 47300 | BH8: =BG8*0.14 -> 6622 | BI8: =BG8*0.12 -> 5676 | BJ8: 400 | BK8: 500 | BL8: =SUM(BG8:BK8) -> 60498 | BM8: 3000 | BN8: 0 | BO8: =IF($F8=50000,0,IF(BL8>40000,200,IF(BL8>25000,150,IF(BL8>15000,130,IF(BL8>10000,110,0))))) -> 200 | BP8: =BL8-BM8-BN8-BO8 -> 57298 | BQ8: 47300 | BR8: =BQ8*0.14 -> 6622 | BS8: =BQ8*0.12 -> 5676 | BT8: 400 | BU8: 500 | BV8: =SUM(BQ8:BU8) -> 60498 | BW8: 3000 | BX8: 0 | BY8: =IF($F8=50000,0,IF(BV8>40000,200,IF(BV8>25000,150,IF(BV8>15000,130,IF(BV8>10000,110,0))))) -> 200 | BZ8: =BV8-BW8-BX8-BY8 -> 57298 | CA8: 47300 | CB8: =CA8*0.14 -> 6622 | CC8: =CA8*0.12 -> 5676 | CD8: 400 | CE8: 500 | CF8: =SUM(CA8:CE8) -> 60498 | CG8: 3000 | CH8: 0 | CI8: =IF($F8=50000,0,IF(CF8>40000,200,IF(CF8>25000,150,IF(CF8>15000,130,IF(CF8>10000,110,0))))) -> 200 | CJ8: =CF8-CG8-CH8-CI8 -> 57298 | CK8: 47300 | CL8: =CK8*0.14 -> 6622 | CM8: =CK8*0.12 -> 5676 | CN8: 400 | CO8: 500 | CP8: =SUM(CK8:CO8) -> 60498 | CQ8: 3000 | CR8: 0 | CS8: =IF($F8=50000,0,IF(CP8>40000,200,IF(CP8>25000,150,IF(CP8>15000,130,IF(CP8>10000,110,0))))) -> 200 | CT8: =CP8-CQ8-CR8-CS8 -> 57298 | CU8: 47300 | CV8: =ROUND(CU8*0.14,0) -> 6622 | CW8: =ROUND(CU8*0.12,0) -> 5676 | CX8: 400 | CY8: 500 | CZ8: =SUM(CU8:CY8) -> 60498 | DA8: 3000 | DB8: 0 | DC8: =IF($F8=50000,0,IF(CZ8>40000,200,IF(CZ8>25000,150,IF(CZ8>15000,130,IF(CZ8>10000,110,0))))) -> 200 | DD8: =CZ8-DA8-DB8-DC8 -> 57298 | DE8: 47300 | DF8: =DE8*0.14 -> 6622 | DG8: =DE8*0.12 -> 5676 | DH8: 400 | DI8: 500 | DJ8: =SUM(DE8:DI8) -> 60498 | DK8: 3000 | DL8: 0 | DM8: =IF($F8=50000,0,IF(DJ8>40000,200,IF(DJ8>25000,150,IF(DJ8>15000,130,IF(DJ8>10000,110,0))))) -> 200 | DN8: =DJ8-DK8-DL8-DM8 -> 57298 | DO8: 47300 | DP8: =DO8*0.14 -> 6622 | DQ8: =DO8*0.12 -> 5676 | DR8: 400 | DS8: 500 | DT8: =SUM(DO8:DS8) -> 60498 | DU8: 3000 | DV8: 0 | DW8: =IF($F8=50000,0,IF(DT8>40000,200,IF(DT8>25000,150,IF(DT8>15000,130,IF(DT8>10000,110,0))))) -> 200 | DX8: =DT8-DU8-DV8-DW8 -> 57298 | DY8: =DT8+DJ8+CZ8+CP8+CF8+BV8+BL8+BB8+AQ8+AG8+W8+M8+G8 -> 717084 | DZ8: =DW8+DM8+DC8+CS8+CI8+BY8+BO8+BE8+AT8+AJ8+Z8+P8 -> 2400 | EA8: =IF(DY8>0,50000,0) -> 50000 | EB8: 0 | EC8: =DY8-DZ8-EA8 -> 664684 | ED8: =DU8+DK8+DA8+CQ8+CG8+BW8+BM8+BC8+AR8+AH8+X8+N8 -> 36000 | EE8: =DV8+DL8+DB8+CR8+CH8+BX8+BN8+BD8+AS8+AI8+Y8+O8 -> 0 | EF8: 0 | EG8: 0 | EH8: 0 | EI8: 0 | EJ8: 0 | EK8: 0 | EL8: 0 | EM8: 0 | EN8: 0 | EO8: 0 | EP8: =SUM(ED8:EO8) -> 36000 | EQ8: =IF(EP8>=150000,150000,EP8) -> 36000 | ER8: =EC8-EQ8 -> 628684 | ES8: 0 | ET8: 0 | EU8: 0 | EV8: 0 | EW8: 0 | EX8: 0 | EY8: 0 | EZ8: =SUM(ES8:EY8)+F8 -> 0 | FA8: =ER8-EZ8 -> 628684 | FB8: =ROUND(IF(FA8>0,IF(FA8>500000,12500,(FA8-250000)*0.05),0),0) -> 12500 | FC8: =IF(ROUND(IF(FA8>0,IF(FA8>1000000,25000,(FA8-500000)*0.2),0),0)<0,0,ROUND(IF(FA8>0,IF(FA8>1000000,25000,(FA8-500000)*0.2),0),0)) -> 25737 | FD8: =FB8+FC8 -> 38237 | FE8: =IF(FD8<12500,0,FD8) -> 38237 | FF8: =FE8*0.04 -> 1529.48 | FG8: =ROUND(FF8+FE8,0) -> 39766 | FH8: 0 | FI8: =FG8-FH8 -> 39766 | FJ8: =IF(DY8>500000,TRUE,FALSE) -> TRUE | FK8: =IF(FJ8,RANDBETWEEN(500,1000),RANDBETWEEN(1000,3000)) -> 930 | FL8: =DY8+FK8 -> 718014 | FM8: =IF(DY8>0,75000,0) -> 75000 | FN8: =FL8-FM8 -> 643014 | FO8: =IF(FN8>1500000,FN8-1500000,0) -> 0 | FP8: =FO8*0.3 -> 0 | FQ8: =IF(FN8>1200000,FN8-1200000-FO8,0) -> 0 | FR8: =FQ8*0.2 -> 0 | FS8: =IF(FN8>1000000,FN8-1000000-F8-FQ8,0) -> 0 | FT8: =FS8*0.15 -> 0 | FU8: =IF(FN8>700000,FN8-700000-FO8-FQ8-FS8,0) -> 0 | FV8: =FU8*0.1 -> 0 | FW8: =IF(FN8>300000,FN8-300000-FO8-FQ8-FS8-FU8,0) -> 343014 | FX8: =FW8*0.05 -> 17150.7 | FY8: =ROUND(FP8+FR8+FT8+FV8+FX8,0) -> 17151 | FZ8: =IF(FN8>700000,FN8,0) -> 0 | GA8: =IF(FN8>700000,FZ8-700000,0) -> 0 | GB8: =IF(FN8<700001,MIN(FY8,25000),0) -> 17151 | GC8: =IF(FN8>700000,FY8-GA8,0) -> 0 | GD8: =IF(GC8>0,TRUE,FALSE) -> FALSE | GE8: =IF(GD8,GC8,0) -> 0 | GF8: =GB8+GE8 -> 17151 | GG8: =ROUND(FY8-GF8,0) -> 0 | GH8: =GG8*0.04 -> 0 | GI8: =ROUNDUP(GG8+GH8,0) -> 0
A9: =_xlfn.AGGREGATE(3,5,$B$2:B9) -> 8 | B9: teachers108 | C9: SUPARNA GHOSH | D9: BER DHAIPUR PRIMARY SCHOOL | E9: WBTPTA | F9: 0 | G9: 6000 | H9: 32500 | I9: =H9*0.1 -> 3250 | J9: =H9*0.12 -> 3900 | K9: 0 | L9: 500 | M9: =SUM(H9:L9) -> 40150 | N9: 5000 | O9: 0 | P9: =IF($F9=50000,0,IF(M9>40000,200,IF(M9>25000,150,IF(M9>15000,130,IF(M9>10000,110,0))))) -> 200 | Q9: =M9-N9-O9-P9 -> 34950 | R9: 32500 | S9: =R9*0.1 -> 3250 | T9: =R9*0.12 -> 3900 | U9: 0 | V9: 500 | W9: =SUM(R9:V9) -> 40150 | X9: 5000 | Y9: 0 | Z9: =IF($F9=50000,0,IF(W9>40000,200,IF(W9>25000,150,IF(W9>15000,130,IF(W9>10000,110,0))))) -> 200 | AA9: =W9-X9-Y9-Z9 -> 34950 | AB9: 32500 | AC9: =AB9*0.14 -> 4550 | AD9: =AB9*0.12 -> 3900 | AE9: 0 | AF9: 500 | AG9: =SUM(AB9:AF9) -> 41450 | AH9: 5000 | AI9: 0 | AJ9: =IF($F9=50000,0,IF(AG9>40000,200,IF(AG9>25000,150,IF(AG9>15000,130,IF(AG9>10000,110,0))))) -> 200 | AK9: =AG9-AH9-AI9-AJ9 -> 36250 | AL9: 32500 | AM9: =AL9*0.14 -> 4550 | AN9: =AL9*0.12 -> 3900 | AO9: 0 | AP9: 500 | AQ9: =SUM(AL9:AP9) -> 41450 | AR9: 5000 | AS9: 0 | AT9: =IF($F9=50000,0,IF(AQ9>40000,200,IF(AQ9>25000,150,IF(AQ9>15000,130,IF(AQ9>10000,110,0))))) -> 200 | AU9: =AQ9-AR9-AS9-AT9 -> 36250 | AV9: 34500 | AW9: =AV9*0.14 -> 4830 | AX9: =R9*0.04 -> 1300 | AY9: =AV9*0.12 -> 4140 | AZ9: 0 | BA9: 500 | BB9: =SUM(AV9:BA9) -> 45270 | BC9: 5000 | BD9: 0 | BE9: =IF($F9=50000,0,IF(BB9>40000,200,IF(BB9>25000,150,IF(BB9>15000,130,IF(BB9>10000,110,0))))) -> 200 | BF9: =BB9-BC9-BD9-BE9 -> 40070 | BG9: 34500 | BH9: =BG9*0.14 -> 4830 | BI9: =BG9*0.12 -> 4140 | BJ9: 0 | BK9: 500 | BL9: =SUM(BG9:BK9) -> 43970 | BM9: 5000 | BN9: 0 | BO9: =IF($F9=50000,0,IF(BL9>40000,200,IF(BL9>25000,150,IF(BL9>15000,130,IF(BL9>10000,110,0))))) -> 200 | BP9: =BL9-BM9-BN9-BO9 -> 38770 | BQ9: 34500 | BR9: =BQ9*0.14 -> 4830 | BS9: =BQ9*0.12 -> 4140 | BT9: 0 | BU9: 500 | BV9: =SUM(BQ9:BU9) -> 43970 | BW9: 5000 | BX9: 0 | BY9: =IF($F9=50000,0,IF(BV9>40000,200,IF(BV9>25000,150,IF(BV9>15000,130,IF(BV9>10000,110,0))))) -> 200 | BZ9: =BV9-BW9-BX9-BY9 -> 38770 | CA9: 34500 | CB9: =CA9*0.14 -> 4830 | CC9: =CA9*0.12 -> 4140 | CD9: 0 | CE9: 500 | CF9: =SUM(CA9:CE9) -> 43970 | CG9: 5000 | CH9: 0 | CI9: =IF($F9=50000,0,IF(CF9>40000,200,IF(CF9>25000,150,IF(CF9>15000,130,IF(CF9>10000,110,0))))) -> 200 | CJ9: =CF9-CG9-CH9-CI9 -> 38770 | CK9: 34500 | CL9: =CK9*0.14 -> 4830 | CM9: =CK9*0.12 -> 4140 | CN9: 0 | CO9: 500 | CP9: =SUM(CK9:CO9) -> 43970 | CQ9: 5000 | CR9: 0 | CS9: =IF($F9=50000,0,IF(CP9>40000,200,IF(CP9>25000,150,IF(CP9>15000,130,IF(CP9>10000,110,0))))) -> 200 | CT9: =CP9-CQ9-CR9-CS9 -> 38770 | CU9: 34500 | CV9: =ROUND(CU9*0.14,0) -> 4830 | CW9: =ROUND(CU9*0.12,0) -> 4140 | CX9: 0 | CY9: 500 | CZ9: =SUM(CU9:CY9) -> 43970 | DA9: 5000 | DB9: 0 | DC9: =IF($F9=50000,0,IF(CZ9>40000,200,IF(CZ9>25000,150,IF(CZ9>15000,130,IF(CZ9>10000,110,0))))) -> 200 | DD9: =CZ9-DA9-DB9-DC9 -> 38770 | DE9: 34500 | DF9: =DE9*0.14 -> 4830 | DG9: =DE9*0.12 -> 4140 | DH9: 0 | DI9: 500 | DJ9: =SUM(DE9:DI9) -> 43970 | DK9: 5000 | DL9: 0 | DM9: =IF($F9=50000,0,IF(DJ9>40000,200,IF(DJ9>25000,150,IF(DJ9>15000,130,IF(DJ9>10000,110,0))))) -> 200 | DN9: =DJ9-DK9-DL9-DM9 -> 38770 | DO9: 34500 | DP9: =DO9*0.14 -> 4830 | DQ9: =DO9*0.12 -> 4140 | DR9: 0 | DS9: 500 | DT9: =SUM(DO9:DS9) -> 43970 | DU9: 5000 | DV9: 0 | DW9: =IF($F9=50000,0,IF(DT9>40000,200,IF(DT9>25000,150,IF(DT9>15000,130,IF(DT9>10000,110,0))))) -> 200 | DX9: =DT9-DU9-DV9-DW9 -> 38770 | DY9: =DT9+DJ9+CZ9+CP9+CF9+BV9+BL9+BB9+AQ9+AG9+W9+M9+G9 -> 522260 | DZ9: =DW9+DM9+DC9+CS9+CI9+BY9+BO9+BE9+AT9+AJ9+Z9+P9 -> 2400 | EA9: =IF(DY9>0,50000,0) -> 50000 | EB9: 0 | EC9: =DY9-DZ9-EA9 -> 469860 | ED9: =DU9+DK9+DA9+CQ9+CG9+BW9+BM9+BC9+AR9+AH9+X9+N9 -> 60000 | EE9: =DV9+DL9+DB9+CR9+CH9+BX9+BN9+BD9+AS9+AI9+Y9+O9 -> 0 | EF9: 0 | EG9: 0 | EH9: 0 | EI9: 0 | EJ9: 0 | EK9: 0 | EL9: 0 | EM9: 0 | EN9: 0 | EO9: 0 | EP9: =SUM(ED9:EO9) -> 60000 | EQ9: =IF(EP9>=150000,150000,EP9) -> 60000 | ER9: =EC9-EQ9 -> 409860 | ES9: 0 | ET9: 0 | EU9: 0 | EV9: 0 | EW9: 0 | EX9: 0 | EY9: 0 | EZ9: =SUM(ES9:EY9)+F9 -> 0 | FA9: =ER9-EZ9 -> 409860 | FB9: =ROUND(IF(FA9>0,IF(FA9>500000,12500,(FA9-250000)*0.05),0),0) -> 7993 | FC9: =IF(ROUND(IF(FA9>0,IF(FA9>1000000,25000,(FA9-500000)*0.2),0),0)<0,0,ROUND(IF(FA9>0,IF(FA9>1000000,25000,(FA9-500000)*0.2),0),0)) -> 0 | FD9: =FB9+FC9 -> 7993 | FE9: =IF(FD9<12500,0,FD9) -> 0 | FF9: =FE9*0.04 -> 0 | FG9: =ROUND(FF9+FE9,0) -> 0 | FH9: 0 | FI9: =FG9-FH9 -> 0 | FJ9: =IF(DY9>500000,TRUE,FALSE) -> TRUE | FK9: =IF(FJ9,RANDBETWEEN(500,1000),RANDBETWEEN(1000,3000)) -> 950 | FL9: =DY9+FK9 -> 523210 | FM9: =IF(DY9>0,75000,0) -> 75000 | FN9: =FL9-FM9 -> 448210 | FO9: =IF(FN9>1500000,FN9-1500000,0) -> 0 | FP9: =FO9*0.3 -> 0 | FQ9: =IF(FN9>1200000,FN9-1200000-FO9,0) -> 0 | FR9: =FQ9*0.2 -> 0 | FS9: =IF(FN9>1000000,FN9-1000000-F9-FQ9,0) -> 0 | FT9: =FS9*0.15 -> 0 | FU9: =IF(FN9>700000,FN9-700000-FO9-FQ9-FS9,0) -> 0 | FV9: =FU9*0.1 -> 0 | FW9: =IF(FN9>300000,FN9-300000-FO9-FQ9-FS9-FU9,0) -> 148210 | FX9: =FW9*0.05 -> 7410.5 | FY9: =ROUND(FP9+FR9+FT9+FV9+FX9,0) -> 7411 | FZ9: =IF(FN9>700000,FN9,0) -> 0 | GA9: =IF(FN9>700000,FZ9-700000,0) -> 0 | GB9: =IF(FN9<700001,MIN(FY9,25000),0) -> 7411 | GC9: =IF(FN9>700000,FY9-GA9,0) -> 0 | GD9: =IF(GC9>0,TRUE,FALSE) -> FALSE | GE9: =IF(GD9,GC9,0) -> 0 | GF9: =GB9+GE9 -> 7411 | GG9: =ROUND(FY9-GF9,0) -> 0 | GH9: =GG9*0.04 -> 0 | GI9: =ROUNDUP(GG9+GH9,0) -> 0
A10: =_xlfn.AGGREGATE(3,5,$B$2:B10) -> 9 | B10: teachers109 | C10: SOHEL REJA | D10: BER DHAIPUR PRIMARY SCHOOL | E10: WBTPTA | F10: 0 | G10: 6000 | H10: 26200 | I10: =H10*0.1 -> 2620 | J10: =H10*0.12 -> 3144 | K10: 0 | L10: 500 | M10: =SUM(H10:L10) -> 32464 | N10: 2000 | O10: 0 | P10: =IF($F10=50000,0,IF(M10>40000,200,IF(M10>25000,150,IF(M10>15000,130,IF(M10>10000,110,0))))) -> 150 | Q10: =M10-N10-O10-P10 -> 30314 | R10: 26200 | S10: =R10*0.1 -> 2620 | T10: =R10*0.12 -> 3144 | U10: 0 | V10: 500 | W10: =SUM(R10:V10) -> 32464 | X10: 2000 | Y10: 0 | Z10: =IF($F10=50000,0,IF(W10>40000,200,IF(W10>25000,150,IF(W10>15000,130,IF(W10>10000,110,0))))) -> 150 | AA10: =W10-X10-Y10-Z10 -> 30314 | AB10: 26200 | AC10: =AB10*0.14 -> 3668 | AD10: =AB10*0.12 -> 3144 | AE10: 0 | AF10: 500 | AG10: =SUM(AB10:AF10) -> 33512 | AH10: 2000 | AI10: 0 | AJ10: =IF($F10=50000,0,IF(AG10>40000,200,IF(AG10>25000,150,IF(AG10>15000,130,IF(AG10>10000,110,0))))) -> 150 | AK10: =AG10-AH10-AI10-AJ10 -> 31362 | AL10: 26200 | AM10: =AL10*0.14 -> 3668 | AN10: =AL10*0.12 -> 3144 | AO10: 0 | AP10: 500 | AQ10: =SUM(AL10:AP10) -> 33512 | AR10: 2000 | AS10: 0 | AT10: =IF($F10=50000,0,IF(AQ10>40000,200,IF(AQ10>25000,150,IF(AQ10>15000,130,IF(AQ10>10000,110,0))))) -> 150 | AU10: =AQ10-AR10-AS10-AT10 -> 31362 | AV10: 27000 | AW10: =AV10*0.14 -> 3780 | AX10: =R10*0.04 -> 1048 | AY10: =AV10*0.12 -> 3240 | AZ10: 0 | BA10: 500 | BB10: =SUM(AV10:BA10) -> 35568 | BC10: 2000 | BD10: 0 | BE10: =IF($F10=50000,0,IF(BB10>40000,200,IF(BB10>25000,150,IF(BB10>15000,130,IF(BB10>10000,110,0))))) -> 150 | BF10: =BB10-BC10-BD10-BE10 -> 33418 | BG10: 27000 | BH10: =BG10*0.14 -> 3780 | BI10: =BG10*0.12 -> 3240 | BJ10: 0 | BK10: 500 | BL10: =SUM(BG10:BK10) -> 34520 | BM10: 2000 | BN10: 0 | BO10: =IF($F10=50000,0,IF(BL10>40000,200,IF(BL10>25000,150,IF(BL10>15000,130,IF(BL10>10000,110,0))))) -> 150 | BP10: =BL10-BM10-BN10-BO10 -> 32370 | BQ10: 27000 | BR10: =BQ10*0.14 -> 3780 | BS10: =BQ10*0.12 -> 3240 | BT10: 0 | BU10: 500 | BV10: =SUM(BQ10:BU10) -> 34520 | BW10: 2000 | BX10: 0 | BY10: =IF($F10=50000,0,IF(BV10>40000,200,IF(BV10>25000,150,IF(BV10>15000,130,IF(BV10>10000,110,0))))) -> 150 | BZ10: =BV10-BW10-BX10-BY10 -> 32370 | CA10: 27000 | CB10: =CA10*0.14 -> 3780 | CC10: =CA10*0.12 -> 3240 | CD10: 0 | CE10: 500 | CF10: =SUM(CA10:CE10) -> 34520 | CG10: 2000 | CH10: 0 | CI10: =IF($F10=50000,0,IF(CF10>40000,200,IF(CF10>25000,150,IF(CF10>15000,130,IF(CF10>10000,110,0))))) -> 150 | CJ10: =CF10-CG10-CH10-CI10 -> 32370 | CK10: 27000 | CL10: =CK10*0.14 -> 3780 | CM10: =CK10*0.12 -> 3240 | CN10: 0 | CO10: 500 | CP10: =SUM(CK10:CO10) -> 34520 | CQ10: 2000 | CR10: 0 | CS10: =IF($F10=50000,0,IF(CP10>40000,200,IF(CP10>25000,150,IF(CP10>15000,130,IF(CP10>10000,110,0))))) -> 150 | CT10: =CP10-CQ10-CR10-CS10 -> 32370 | CU10: 27000 | CV10: =ROUND(CU10*0.14,0) -> 3780 | CW10: =ROUND(CU10*0.12,0) -> 3240 | CX10: 0 | CY10: 500 | CZ10: =SUM(CU10:CY10) -> 34520 | DA10: 2000 | DB10: 0 | DC10: =IF($F10=50000,0,IF(CZ10>40000,200,IF(CZ10>25000,150,IF(CZ10>15000,130,IF(CZ10>10000,110,0))))) -> 150 | DD10: =CZ10-DA10-DB10-DC10 -> 32370 | DE10: 27000 | DF10: =DE10*0.14 -> 3780 | DG10: =DE10*0.12 -> 3240 | DH10: 0 | DI10: 500 | DJ10: =SUM(DE10:DI10) -> 34520 | DK10: 2000 | DL10: 0 | DM10: =IF($F10=50000,0,IF(DJ10>40000,200,IF(DJ10>25000,150,IF(DJ10>15000,130,IF(DJ10>10000,110,0))))) -> 150 | DN10: =DJ10-DK10-DL10-DM10 -> 32370 | DO10: 27000 | DP10: =DO10*0.14 -> 3780 | DQ10: =DO10*0.12 -> 3240 | DR10: 0 | DS10: 500 | DT10: =SUM(DO10:DS10) -> 34520 | DU10: 2000 | DV10: 0 | DW10: =IF($F10=50000,0,IF(DT10>40000,200,IF(DT10>25000,150,IF(DT10>15000,130,IF(DT10>10000,110,0))))) -> 150 | DX10: =DT10-DU10-DV10-DW10 -> 32370 | DY10: =DT10+DJ10+CZ10+CP10+CF10+BV10+BL10+BB10+AQ10+AG10+W10+M10+G10 -> 415160 | DZ10: =DW10+DM10+DC10+CS10+CI10+BY10+BO10+BE10+AT10+AJ10+Z10+P10 -> 1800 | EA10: =IF(DY10>0,50000,0) -> 50000 | EB10: 0 | EC10: =DY10-DZ10-EA10 -> 363360 | ED10: =DU10+DK10+DA10+CQ10+CG10+BW10+BM10+BC10+AR10+AH10+X10+N10 -> 24000 | EE10: =DV10+DL10+DB10+CR10+CH10+BX10+BN10+BD10+AS10+AI10+Y10+O10 -> 0 | EF10: 0 | EG10: 0 | EH10: 0 | EI10: 0 | EJ10: 0 | EK10: 0 | EL10: 0 | EM10: 0 | EN10: 0 | EO10: 0 | EP10: =SUM(ED10:EO10) -> 24000 | EQ10: =IF(EP10>=150000,150000,EP10) -> 24000 | ER10: =EC10-EQ10 -> 339360 | ES10: 0 | ET10: 0 | EU10: 0 | EV10: 0 | EW10: 0 | EX10: 0 | EY10: 0 | EZ10: =SUM(ES10:EY10)+F10 -> 0 | FA10: =ER10-EZ10 -> 339360 | FB10: =ROUND(IF(FA10>0,IF(FA10>500000,12500,(FA10-250000)*0.05),0),0) -> 4468 | FC10: =IF(ROUND(IF(FA10>0,IF(FA10>1000000,25000,(FA10-500000)*0.2),0),0)<0,0,ROUND(IF(FA10>0,IF(FA10>1000000,25000,(FA10-500000)*0.2),0),0)) -> 0 | FD10: =FB10+FC10 -> 4468 | FE10: =IF(FD10<12500,0,FD10) -> 0 | FF10: =FE10*0.04 -> 0 | FG10: =ROUND(FF10+FE10,0) -> 0 | FH10: 0 | FI10: =FG10-FH10 -> 0 | FJ10: =IF(DY10>500000,TRUE,FALSE) -> FALSE | FK10: =IF(FJ10,RANDBETWEEN(500,1000),RANDBETWEEN(1000,3000)) -> 2493 | FL10: =DY10+FK10 -> 417653 | FM10: =IF(DY10>0,75000,0) -> 75000 | FN10: =FL10-FM10 -> 342653 | FO10: =IF(FN10>1500000,FN10-1500000,0) -> 0 | FP10: =FO10*0.3 -> 0 | FQ10: =IF(FN10>1200000,FN10-1200000-FO10,0) -> 0 | FR10: =FQ10*0.2 -> 0 | FS10: =IF(FN10>1000000,FN10-1000000-F10-FQ10,0) -> 0 | FT10: =FS10*0.15 -> 0 | FU10: =IF(FN10>700000,FN10-700000-FO10-FQ10-FS10,0) -> 0 | FV10: =FU10*0.1 -> 0 | FW10: =IF(FN10>300000,FN10-300000-FO10-FQ10-FS10-FU10,0) -> 42653 | FX10: =FW10*0.05 -> 2132.65 | FY10: =ROUND(FP10+FR10+FT10+FV10+FX10,0) -> 2133 | FZ10: =IF(FN10>700000,FN10,0) -> 0 | GA10: =IF(FN10>700000,FZ10-700000,0) -> 0 | GB10: =IF(FN10<700001,MIN(FY10,25000),0) -> 2133 | GC10: =IF(FN10>700000,FY10-GA10,0) -> 0 | GD10: =IF(GC10>0,TRUE,FALSE) -> FALSE | GE10: =IF(GD10,GC10,0) -> 0 | GF10: =GB10+GE10 -> 2133 | GG10: =ROUND(FY10-GF10,0) -> 0 | GH10: =GG10*0.04 -> 0 | GI10: =ROUNDUP(GG10+GH10,0) -> 0
